Workbook

Sheet SEMANA 14
B1: 🌟 | C1: 🌟🌟 | D1: 🌟🌟🌟 | E1: 🌟🌟🌟🌟 | F1: 🌟🌟🌟🌟🌟 | G1: TOTAL DE VOTOS / REFEIÇÃO | H1: TOTAL POR DIA | O1: 1 | P1: 1 | Q1: 11 | R1: 23 | S1: 26
A2: Segunda (Almoço) | B2: 1 | C2: 1 | D2: 11 | E2: 23 | F2: 26 | G2: =SUM(B2:F2) -> 62 | H2: =SUM(G2:G5) -> 101 | O2: 2 | P2: 2 | Q2: 8 | R2: 20 | S2: 7
A3: Segunda (Almoço) #2 | G3: =SUM(B3:F3) -> 0 | O3: 3 | P3: 11 | Q3: 23 | R3: 18 | S3: 19
A4: Segunda (Janta) | B4: 2 | C4: 2 | D4: 8 | E4: 20 | F4: 7 | G4: =SUM(B4:F4) -> 39 | O4: 28 | P4: 0 | Q4: 5 | R4: 11 | S4: 12
A5: Segunda (Janta) #2 | G5: =SUM(B5:F5) -> 0 | O5: 1 | P5: 0 | Q5: 2 | R5: 15 | S5: 38
A6: Terça (Almoço) | B6: 3 | C6: 11 | D6: 23 | E6: 18 | F6: 19 | G6: =SUM(B6:F6) -> 74 | H6: =SUM(G6:G9) -> 130 | O6: 2 | P6: 2 | Q6: 12 | R6: 12 | S6: 17
A7: Terça (Almoço) #2 | G7: =SUM(B7:F7) -> 0 | O7: 4 | P7: 12 | Q7: 16 | R7: 20 | S7: 3
A8: Terça (Janta) | B8: 28 | C8: 0 | D8: 5 | E8: 11 | F8: 12 | G8: =SUM(B8:F8) -> 56 | O8: 2 | P8: 1 | Q8: 1 | R8: 7 | S8: 52
A9: Terça (Janta) #2 | G9: =SUM(B9:F9) -> 0 | O9: 3 | P9: 4 | Q9: 2 | R9: 19 | S9: 27
A10: Quarta (Almoço) | B10: 1 | C10: 0 | D10: 2 | E10: 15 | F10: 38 | G10: =SUM(B10:F10) -> 56 | H10: =SUM(G10:G13) -> 101 | O10: 3 | P10: 0 | Q10: 2 | R10: 7 | S10: 25
A11: Quarta (Almoço) #2 | G11: =SUM(B11:F11) -> 0 | O11: 21 | P11: 9 | Q11: 16 | R11: 10 | S11: 5
A12: Quarta (Janta) | B12: 2 | C12: 2 | D12: 12 | E12: 12 | F12: 17 | G12: =SUM(B12:F12) -> 45
A13: Quarta (Janta) #2 | G13: =SUM(B13:F13) -> 0
A14: Quinta (Almoço) | B14: 4 | C14: 12 | D14: 16 | E14: 20 | F14: 3 | G14: =SUM(B14:F14) -> 55 | H14: =SUM(G14:G17) -> 118
A15: Quinta (Almoço) #2 | G15: =SUM(B15:F15) -> 0
A16: Quinta (Janta) | B16: 2 | C16: 1 | D16: 1 | E16: 7 | F16: 52 | G16: =SUM(B16:F16) -> 63
A17: Quinta (Janta) #2 | G17: =SUM(B17:F17) -> 0
A18: Sexta (Almoço) | B18: 3 | C18: 4 | D18: 2 | E18: 19 | F18: 27 | G18: =SUM(B18:F18) -> 55 | H18: =SUM(G18:G21) -> 92
A19: Sexta (Almoço) #2 | G19: =SUM(B19:F19) -> 0
A20: Sexta (Janta) | B20: 3 | C20: 0 | D20: 2 | E20: 7 | F20: 25 | G20: =SUM(B20:F20) -> 37
A21: Sexta (Janta) #2 | G21: =SUM(B21:F21) -> 0
A22: Sábado | B22: 21 | C22: 9 | D22: 16 | E22: 10 | F22: 5 | G22: =SUM(B22:F22) -> 61 | H22: =SUM(G22:G24) -> 61
A23: Sábado #2 | G23: =SUM(B23:F23) -> 0
A25: TOTAL DE ESTRELAS | B25: =SUM(B2:B23) -> 70 | C25: =SUM(C2:C23) -> 42 | D25: =SUM(D2:D23) -> 98 | E25: =SUM(E2:E23) -> 162 | F25: =SUM(F2:F23) -> 231 | G25: TOTAL DE VOTOS | H25: =SUM(G2:G23) -> 603
A26: MEDIA POR ESTRELA | B26: =AVERAGE(B2:B23) -> 6.3636364 | C26: =AVERAGE(C2:C23) -> 3.8181818 | D26: =AVERAGE(D2:D23) -> 8.9090909 | E26: =AVERAGE(E2:E23) -> 14.727273 | F26: =AVERAGE(F2:F23) -> 21 | G26: MÉDIA DAS ESTRELAS | H26: =SUM(B25*1,C25*2,D25*3,E25*4,F25*5)/H25 -> 3.7330017
G27: MÉDIA ANTERIOR | H27: 0 | I27: =_xlfn.CONCAT("", (H26-H27)/H27, "%") -> #DIV/0!

Sheet SEMANA 15
B1: 🌟 | C1: 🌟🌟 | D1: 🌟🌟🌟 | E1: 🌟🌟🌟🌟 | F1: 🌟🌟🌟🌟🌟 | G1: TOTAL DE VOTOS / REFEIÇÃO | H1: TOTAL POR DIA | N1: 8 | O1: 6 | P1: 18 | Q1: 30 | R1: 14
A2: Segunda (Almoço) | B2: 8 | C2: 6 | D2: 18 | E2: 30 | F2: 14 | G2: =SUM(B2:F2) -> 76 | H2: =SUM(G2:G5) -> 131 | N2: 1 | O2: 5 | P2: 1 | Q2: 9 | R2: 39
A3: Segunda (Almoço) #2 | G3: =SUM(B3:F3) -> 0 | N3: 3 | O3: 1 | P3: 15 | Q3: 24 | R3: 34
A4: Segunda (Janta) | B4: 1 | C4: 5 | D4: 1 | E4: 9 | F4: 39 | G4: =SUM(B4:F4) -> 55 | N4: 0 | O4: 1 | P4: 12 | Q4: 21 | R4: 34
A5: Segunda (Janta) #2 | G5: =SUM(B5:F5) -> 0 | N5: 26 | O5: 13 | P5: 24 | Q5: 9 | R5: 4
A6: Terça (Almoço) | B6: 3 | C6: 1 | D6: 15 | E6: 24 | F6: 34 | G6: =SUM(B6:F6) -> 77 | H6: =SUM(G6:G9) -> 145 | N6: 2 | O6: 1 | P6: 3 | Q6: 12 | R6: 29
A7: Terça (Almoço) #2 | G7: =SUM(B7:F7) -> 0 | N7: 3 | O7: 1 | P7: 13 | Q7: 23 | R7: 18
A8: Terça (Janta) | B8: 0 | C8: 1 | D8: 12 | E8: 21 | F8: 34 | G8: =SUM(B8:F8) -> 68 | N8: 0 | O8: 4 | P8: 6 | Q8: 7 | R8: 20
A9: Terça (Janta) #2 | G9: =SUM(B9:F9) -> 0 | N9: 1 | O9: 3 | P9: 13 | Q9: 20 | R9: 2
A10: Quarta (Almoço) | B10: 26 | C10: 13 | D10: 24 | E10: 9 | F10: 4 | G10: =SUM(B10:F10) -> 76 | H10: =SUM(G10:G13) -> 123 | N10: 1 | O10: 0 | P10: 6 | Q10: 5 | R10: 12
A11: Quarta (Almoço) #2 | G11: =SUM(B11:F11) -> 0 | N11: 0 | O11: 0 | P11: 4 | Q11: 4 | R11: 23
A12: Quarta (Janta) | B12: 2 | C12: 1 | D12: 3 | E12: 12 | F12: 29 | G12: =SUM(B12:F12) -> 47
A13: Quarta (Janta) #2 | G13: =SUM(B13:F13) -> 0
A14: Quinta (Almoço) | B14: 3 | C14: 1 | D14: 13 | E14: 23 | F14: 18 | G14: =SUM(B14:F14) -> 58 | H14: =SUM(G14:G17) -> 95
A15: Quinta (Almoço) #2 | G15: =SUM(B15:F15) -> 0
A16: Quinta (Janta) | B16: 0 | C16: 4 | D16: 6 | E16: 7 | F16: 20 | G16: =SUM(B16:F16) -> 37
A17: Quinta (Janta) #2 | G17: =SUM(B17:F17) -> 0
A18: Sexta (Almoço) | B18: 1 | C18: 3 | D18: 13 | E18: 20 | F18: 2 | G18: =SUM(B18:F18) -> 39 | H18: =SUM(G18:G21) -> 63
A19: Sexta (Almoço) #2 | G19: =SUM(B19:F19) -> 0
A20: Sexta (Janta) | B20: 1 | C20: 0 | D20: 6 | E20: 5 | F20: 12 | G20: =SUM(B20:F20) -> 24
A21: Sexta (Janta) #2 | G21: =SUM(B21:F21) -> 0
A22: Sábado | B22: 0 | C22: 0 | D22: 4 | E22: 4 | F22: 23 | G22: =SUM(B22:F22) -> 31 | H22: =SUM(G22:G24) -> 31
A23: Sábado #2 | G23: =SUM(B23:F23) -> 0
A25: TOTAL DE ESTRELAS | B25: =SUM(B2:B23) -> 45 | C25: =SUM(C2:C23) -> 35 | D25: =SUM(D2:D23) -> 115 | E25: =SUM(E2:E23) -> 164 | F25: =SUM(F2:F23) -> 229 | G25: TOTAL DE VOTOS | H25: =SUM(G2:G23) -> 588
A26: MEDIA POR ESTRELA | B26: =AVERAGE(B2:B23) -> 4.0909091 | C26: =AVERAGE(C2:C23) -> 3.1818182 | D26: =AVERAGE(D2:D23) -> 10.454545 | E26: =AVERAGE(E2:E23) -> 14.909091 | F26: =AVERAGE(F2:F23) -> 20.818182 | G26: MÉDIA DAS ESTRELAS | H26: =SUM(B25*1,C25*2,D25*3,E25*4,F25*5)/H25 -> 3.8452381
G27: MÉDIA ANTERIOR | H27: ='SEMANA 14'!H26 -> 3.7330017 | I27: =_xlfn.CONCAT("", (H26-H27)/H27, "%") -> 0,0300660024116266%

Sheet SEMANA 16
B1: 🌟 | C1: 🌟🌟 | D1: 🌟🌟🌟 | E1: 🌟🌟🌟🌟 | F1: 🌟🌟🌟🌟🌟 | G1: TOTAL DE VOTOS / REFEIÇÃO | H1: TOTAL POR DIA | N1: 3 | O1: 0 | P1: 16 | Q1: 33 | R1: 19
A2: Segunda (Almoço) | B2: 3 | C2: 0 | D2: 16 | E2: 33 | F2: 19 | G2: =SUM(B2:F2) -> 71 | H2: =SUM(G2:G5) -> 130 | N2: 0 | O2: 1 | P2: 2 | Q2: 17 | R2: 39
A3: Segunda (Almoço) #2 | G3: =SUM(B3:F3) -> 0 | N3: 12 | O3: 9 | P3: 35 | Q3: 13 | R3: 8
A4: Segunda (Janta) | B4: 0 | C4: 1 | D4: 2 | E4: 17 | F4: 39 | G4: =SUM(B4:F4) -> 59 | N4: 1 | O4: 0 | P4: 0 | Q4: 15 | R4: 35
A5: Segunda (Janta) #2 | G5: =SUM(B5:F5) -> 0 | N5: 16 | O5: 4 | P5: 14 | Q5: 11 | R5: 29
A6: Terça (Almoço) | B6: 12 | C6: 9 | D6: 35 | E6: 13 | F6: 8 | G6: =SUM(B6:F6) -> 77 | H6: =SUM(G6:G9) -> 128 | N6: 0 | O6: 0 | P6: 1 | Q6: 0 | R6: 72
A7: Terça (Almoço) #2 | G7: =SUM(B7:F7) -> 0 | N7: 0 | O7: 3 | P7: 5 | Q7: 10 | R7: 55
A8: Terça (Janta) | B8: 1 | C8: 0 | D8: 0 | E8: 15 | F8: 35 | G8: =SUM(B8:F8) -> 51 | N8: 0 | O8: 0 | P8: 0 | Q8: 5 | R8: 20
A9: Terça (Janta) #2 | G9: =SUM(B9:F9) -> 0 | N9: 1 | O9: 2 | P9: 2 | Q9: 13 | R9: 20
A10: Quarta (Almoço) | B10: 16 | C10: 4 | D10: 14 | E10: 11 | F10: 29 | G10: =SUM(B10:F10) -> 74 | H10: =SUM(G10:G13) -> 147 | N10: 10 | O10: 2 | P10: 3 | Q10: 8 | R10: 10
A11: Quarta (Almoço) #2 | G11: =SUM(B11:F11) -> 0 | N11: 4 | O11: 2 | P11: 3 | Q11: 9 | R11: 17
A12: Quarta (Janta) | B12: 0 | C12: 0 | D12: 1 | E12: 0 | F12: 72 | G12: =SUM(B12:F12) -> 73
A13: Quarta (Janta) #2 | G13: =SUM(B13:F13) -> 0
A14: Quinta (Almoço) | B14: 0 | C14: 3 | D14: 5 | E14: 10 | F14: 55 | G14: =SUM(B14:F14) -> 73 | H14: =SUM(G14:G17) -> 98
A15: Quinta (Almoço) #2 | G15: =SUM(B15:F15) -> 0
A16: Quinta (Janta) | B16: 0 | C16: 0 | D16: 0 | E16: 5 | F16: 20 | G16: =SUM(B16:F16) -> 25
A17: Quinta (Janta) #2 | G17: =SUM(B17:F17) -> 0
A18: Sexta (Almoço) | B18: 1 | C18: 2 | D18: 2 | E18: 13 | F18: 20 | G18: =SUM(B18:F18) -> 38 | H18: =SUM(G18:G21) -> 71
A19: Sexta (Almoço) #2 | G19: =SUM(B19:F19) -> 0
A20: Sexta (Janta) | B20: 10 | C20: 2 | D20: 3 | E20: 8 | F20: 10 | G20: =SUM(B20:F20) -> 33
A21: Sexta (Janta) #2 | G21: =SUM(B21:F21) -> 0
A22: Sábado | B22: 4 | C22: 2 | D22: 3 | E22: 9 | F22: 17 | G22: =SUM(B22:F22) -> 35 | H22: =SUM(G22:G24) -> 35
A23: Sábado #2 | G23: =SUM(B23:F23) -> 0
A25: TOTAL DE ESTRELAS | B25: =SUM(B2:B23) -> 47 | C25: =SUM(C2:C23) -> 23 | D25: =SUM(D2:D23) -> 81 | E25: =SUM(E2:E23) -> 134 | F25: =SUM(F2:F23) -> 324 | G25: TOTAL DE VOTOS | H25: =SUM(G2:G23) -> 609
A26: MEDIA POR ESTRELA | B26: =AVERAGE(B2:B23) -> 4.2727273 | C26: =AVERAGE(C2:C23) -> 2.0909091 | D26: =AVERAGE(D2:D23) -> 7.3636364 | E26: =AVERAGE(E2:E23) -> 12.181818 | F26: =AVERAGE(F2:F23) -> 29.454545 | G26: MÉDIA DAS ESTRELAS | H26: =SUM(B25*1,C25*2,D25*3,E25*4,F25*5)/H25 -> 4.091954
G27: MÉDIA ANTERIOR | H27: ='SEMANA 15'!H26 -> 3.8452381 | I27: =_xlfn.CONCAT("", (H26-H27)/H27, "%") -> 0,0641614177431408%

Sheet SEMANA 17
B1: 🌟 | C1: 🌟🌟 | D1: 🌟🌟🌟 | E1: 🌟🌟🌟🌟 | F1: 🌟🌟🌟🌟🌟 | G1: TOTAL DE VOTOS / REFEIÇÃO | H1: TOTAL POR DIA | N1: 1 | O1: 3 | P1: 24 | Q1: 23 | R1: 9
A2: Segunda (Almoço) | B2: 1 | C2: 3 | D2: 24 | E2: 23 | F2: 9 | G2: =SUM(B2:F2) -> 60 | H2: =SUM(G2:G5) -> 103 | N2: 0 | O2: 4 | P2: 10 | Q2: 18 | R2: 11
A3: Segunda (Almoço) #2 | G3: =SUM(B3:F3) -> 0 | N3: 0 | O3: 0 | P3: 1 | Q3: 10 | R3: 15
A4: Segunda (Janta) | B4: 0 | C4: 4 | D4: 10 | E4: 18 | F4: 11 | G4: =SUM(B4:F4) -> 43 | N4: 0 | O4: 1 | P4: 3 | Q4: 8 | R4: 40
A5: Segunda (Janta) #2 | G5: =SUM(B5:F5) -> 0 | N5: 1 | O5: 8 | P5: 12 | Q5: 21 | R5: 3
A6: Terça (Almoço) | B6: 0 | C6: 0 | D6: 1 | E6: 10 | F6: 15 | G6: =SUM(B6:F6) -> 26 | H6: =SUM(G6:G9) -> 78 | N6: 0 | O6: 0 | P6: 12 | Q6: 15 | R6: 23
A7: Terça (Almoço) #2 | G7: =SUM(B7:F7) -> 0 | N7: 6 | O7: 7 | P7: 13 | Q7: 24 | R7: 16
A8: Terça (Janta) | B8: 0 | C8: 1 | D8: 3 | E8: 8 | F8: 40 | G8: =SUM(B8:F8) -> 52 | N8: 0 | O8: 0 | P8: 0 | Q8: 11 | R8: 17
A9: Terça (Janta) #2 | G9: =SUM(B9:F9) -> 0 | N9: 0 | O9: 0 | P9: 0 | Q9: 1 | R9: 4
A10: Quarta (Almoço) | B10: 1 | C10: 8 | D10: 12 | E10: 21 | F10: 3 | G10: =SUM(B10:F10) -> 45 | H10: =SUM(G10:G13) -> 95 | N10: 0 | O10: 0 | P10: 0 | Q10: 0 | R10: 0
A11: Quarta (Almoço) #2 | G11: =SUM(B11:F11) -> 0 | N11: 0 | O11: 0 | P11: 0 | Q11: 0 | R11: 0
A12: Quarta (Janta) | B12: 0 | C12: 0 | D12: 12 | E12: 15 | F12: 23 | G12: =SUM(B12:F12) -> 50
A13: Quarta (Janta) #2 | G13: =SUM(B13:F13) -> 0
A14: Quinta (Almoço) | B14: 6 | C14: 7 | D14: 13 | E14: 24 | F14: 16 | G14: =SUM(B14:F14) -> 66 | H14: =SUM(G14:G17) -> 94
A15: Quinta (Almoço) #2 | G15: =SUM(B15:F15) -> 0
A16: Quinta (Janta) | B16: 0 | C16: 0 | D16: 0 | E16: 11 | F16: 17 | G16: =SUM(B16:F16) -> 28
A17: Quinta (Janta) #2 | G17: =SUM(B17:F17) -> 0
A18: Sexta (Almoço) | B18: 0 | C18: 0 | D18: 0 | E18: 1 | F18: 4 | G18: =SUM(B18:F18) -> 5 | H18: =SUM(G18:G21) -> 5
A19: Sexta (Almoço) #2 | G19: =SUM(B19:F19) -> 0
A20: Sexta (Janta) | G20: =SUM(B20:F20) -> 0
A21: Sexta (Janta) #2 | G21: =SUM(B21:F21) -> 0
A22: Sábado | G22: =SUM(B22:F22) -> 0 | H22: =SUM(G22:G24) -> 0
A23: Sábado #2 | G23: =SUM(B23:F23) -> 0
A25: TOTAL DE ESTRELAS | B25: =SUM(B2:B23) -> 8 | C25: =SUM(C2:C23) -> 23 | D25: =SUM(D2:D23) -> 75 | E25: =SUM(E2:E23) -> 131 | F25: =SUM(F2:F23) -> 138 | G25: TOTAL DE VOTOS | H25: =SUM(G2:G23) -> 375
A26: MEDIA POR ESTRELA | B26: =AVERAGE(B2:B23) -> 0.88888889 | C26: =AVERAGE(C2:C23) -> 2.5555556 | D26: =AVERAGE(D2:D23) -> 8.3333333 | E26: =AVERAGE(E2:E23) -> 14.555556 | F26: =AVERAGE(F2:F23) -> 15.333333 | G26: MÉDIA DAS ESTRELAS | H26: =SUM(B25*1,C25*2,D25*3,E25*4,F25*5)/H25 -> 3.9813333
G27: MÉDIA ANTERIOR | H27: ='SEMANA 16'!H26 -> 4.091954 | I27: =_xlfn.CONCAT("", (H26-H27)/H27, "%") -> -0,0270337078651686%

Sheet SEMANA 21
B1: 🌟 | C1: 🌟🌟 | D1: 🌟🌟🌟 | E1: 🌟🌟🌟🌟 | F1: 🌟🌟🌟🌟🌟 | G1: TOTAL DE VOTOS / REFEIÇÃO | H1: TOTAL POR DIA | N1: 2 | O1: 0 | P1: 2 | Q1: 1 | R1: 51
A2: Segunda (Almoço) | B2: 2 | C2: 0 | D2: 2 | E2: 1 | F2: 51 | G2: =SUM(B2:F2) -> 56 | H2: =SUM(G2:G5) -> 88 | N2: 3 | O2: 4 | P2: 3 | Q2: 6 | R2: 16
A3: Segunda (Almoço) #2 | G3: =SUM(B3:F3) -> 0 | N3: 1 | O3: 1 | P3: 7 | Q3: 20 | R3: 8
A4: Segunda (Janta) | B4: 3 | C4: 4 | D4: 3 | E4: 6 | F4: 16 | G4: =SUM(B4:F4) -> 32 | N4: 0 | O4: 2 | P4: =3+1 -> 4 | Q4: 10 | R4: 25
A5: Segunda (Janta) #2 | G5: =SUM(B5:F5) -> 0 | N5: 1 | O5: 1 | P5: 7 | Q5: 22 | R5: =15+6 -> 21
A6: Terça (Almoço) | B6: 1 | C6: 1 | D6: 7 | E6: 20 | F6: 8 | G6: =SUM(B6:F6) -> 37 | H6: =SUM(G6:G9) -> 78 | N6: 1 | O6: 0 | P6: 4 | Q6: 9 | R6: 28
A7: Terça (Almoço) #2 | G7: =SUM(B7:F7) -> 0 | N7: 0 | O7: 1 | P7: 6 | Q7: 19 | R7: 9
A8: Terça (Janta) | B8: 0 | C8: 2 | D8: 4 | E8: 10 | F8: 25 | G8: =SUM(B8:F8) -> 41 | N8: 0 | O8: 1 | P8: 3 | Q8: 10 | R8: 18
A9: Terça (Janta) #2 | G9: =SUM(B9:F9) -> 0 | N9: 0 | O9: 7 | P9: 10 | Q9: 13 | R9: 6
A10: Quarta (Almoço) | B10: 1 | C10: 1 | D10: 7 | E10: 22 | F10: 21 | G10: =SUM(B10:F10) -> 52 | H10: =SUM(G10:G13) -> 94 | N10: 25 | O10: 8 | P10: 1 | Q10: 1 | R10: 2
A11: Quarta (Almoço) #2 | G11: =SUM(B11:F11) -> 0 | N11: 0 | O11: 0 | P11: 3 | Q11: 5 | R11: =13+7 -> 20
A12: Quarta (Janta) | B12: 1 | C12: 0 | D12: 4 | E12: 9 | F12: 28 | G12: =SUM(B12:F12) -> 42
A13: Quarta (Janta) #2 | G13: =SUM(B13:F13) -> 0
A14: Quinta (Almoço) | B14: 0 | C14: 1 | D14: 6 | E14: 19 | F14: 9 | G14: =SUM(B14:F14) -> 35 | H14: =SUM(G14:G17) -> 67
A15: Quinta (Almoço) #2 | G15: =SUM(B15:F15) -> 0
A16: Quinta (Janta) | B16: 0 | C16: 1 | D16: 3 | E16: 10 | F16: 18 | G16: =SUM(B16:F16) -> 32
A17: Quinta (Janta) #2 | G17: =SUM(B17:F17) -> 0
A18: Sexta (Almoço) | B18: 0 | C18: 7 | D18: 10 | E18: 13 | F18: 6 | G18: =SUM(B18:F18) -> 36 | H18: =SUM(G18:G21) -> 73
A19: Sexta (Almoço) #2 | G19: =SUM(B19:F19) -> 0
A20: Sexta (Janta) | B20: 25 | C20: 8 | D20: 1 | E20: 1 | F20: 2 | G20: =SUM(B20:F20) -> 37
A21: Sexta (Janta) #2 | G21: =SUM(B21:F21) -> 0
A22: Sábado | B22: 0 | C22: 0 | D22: 3 | E22: 5 | F22: 20 | G22: =SUM(B22:F22) -> 28 | H22: =SUM(G22:G24) -> 28
A23: Sábado #2 | G23: =SUM(B23:F23) -> 0
A25: TOTAL DE ESTRELAS | B25: =SUM(B2:B23) -> 33 | C25: =SUM(C2:C23) -> 25 | D25: =SUM(D2:D23) -> 50 | E25: =SUM(E2:E23) -> 116 | F25: =SUM(F2:F23) -> 204 | G25: TOTAL DE VOTOS | H25: =SUM(G2:G23) -> 428
A26: MEDIA POR ESTRELA | B26: =AVERAGE(B2:B23) -> 3 | C26: =AVERAGE(C2:C23) -> 2.2727273 | D26: =AVERAGE(D2:D23) -> 4.5454545 | E26: =AVERAGE(E2:E23) -> 10.545455 | F26: =AVERAGE(F2:F23) -> 18.545455 | G26: MÉDIA DAS ESTRELAS | H26: =SUM(B25*1,C25*2,D25*3,E25*4,F25*5)/H25 -> 4.0116822
G27: MÉDIA ANTERIOR | H27: ='SEMANA 17'!H26 -> 3.9813333 | I27: =_xlfn.CONCAT("", (H26-H27)/H27, "%") -> 0,007622800483252%

Sheet SEMANA 22
B1: 🌟 | C1: 🌟🌟 | D1: 🌟🌟🌟 | E1: 🌟🌟🌟🌟 | F1: 🌟🌟🌟🌟🌟 | G1: TOTAL DE VOTOS / REFEIÇÃO | H1: TOTAL POR DIA
A2: Segunda (Almoço) | B2: 2 | C2: 0 | D2: 7 | E2: 14 | F2: 21 | G2: =SUM(B2:F2) -> 44 | H2: =SUM(G2:G5) -> 87
A3: Segunda (Almoço) #2 | B3: 0 | C3: 0 | D3: 0 | E3: 6 | F3: 1 | G3: =SUM(B3:F3) -> 7
A4: Segunda (Janta) | B4: 2 | C4: 2 | D4: 2 | E4: 15 | F4: 5 | G4: =SUM(B4:F4) -> 26
A5: Segunda (Janta) #2 | B5: 0 | C5: 0 | D5: 0 | E5: 6 | F5: 4 | G5: =SUM(B5:F5) -> 10
A6: Terça (Almoço) | B6: 4 | C6: 0 | D6: 5 | E6: 19 | F6: 21 | G6: =SUM(B6:F6) -> 49 | H6: =SUM(G6:G9) -> 108
A7: Terça (Almoço) #2 | B7: 0 | C7: 0 | D7: 0 | E7: 3 | F7: 10 | G7: =SUM(B7:F7) -> 13
A8: Terça (Janta) | B8: 4 | C8: 1 | D8: 5 | E8: 5 | F8: 26 | G8: =SUM(B8:F8) -> 41
A9: Terça (Janta) #2 | B9: 0 | C9: 0 | D9: 0 | E9: 3 | F9: 2 | G9: =SUM(B9:F9) -> 5
A10: Quarta (Almoço) | B10: 6 | C10: 8 | D10: 18 | E10: 22 | F10: 11 | G10: =SUM(B10:F10) -> 65 | H10: =SUM(G10:G13) -> 119
A11: Quarta (Almoço) #2 | B11: 1 | C11: 1 | D11: 12 | E11: 8 | F11: 2 | G11: =SUM(B11:F11) -> 24
A12: Quarta (Janta) | B12: 1 | C12: 1 | D12: 0 | E12: 5 | F12: 11 | G12: =SUM(B12:F12) -> 18
A13: Quarta (Janta) #2 | B13: 0 | C13: 0 | D13: 0 | E13: 9 | F13: 3 | G13: =SUM(B13:F13) -> 12
A14: Quinta (Almoço) | G14: =SUM(B14:F14) -> 0 | H14: =SUM(G14:G17) -> 0
A15: Quinta (Almoço) #2 | G15: =SUM(B15:F15) -> 0
A16: Quinta (Janta) | G16: =SUM(B16:F16) -> 0
A17: Quinta (Janta) #2 | G17: =SUM(B17:F17) -> 0
A18: Sexta (Almoço) | G18: =SUM(B18:F18) -> 0 | H18: =SUM(G18:G21) -> 0
A19: Sexta (Almoço) #2 | G19: =SUM(B19:F19) -> 0
A20: Sexta (Janta) | G20: =SUM(B20:F20) -> 0
A21: Sexta (Janta) #2 | G21: =SUM(B21:F21) -> 0
A22: Sábado | G22: =SUM(B22:F22) -> 0 | H22: =SUM(G22:G24) -> 0
A23: Sábado #2 | G23: =SUM(B23:F23) -> 0
A25: TOTAL DE ESTRELAS | B25: =SUM(B2:B23) -> 20 | C25: =SUM(C2:C23) -> 13 | D25: =SUM(D2:D23) -> 49 | E25: =SUM(E2:E23) -> 115 | F25: =SUM(F2:F22) -> 117 | G25: TOTAL DE VOTOS | H25: =SUM(G2:G23) -> 314
A26: MEDIA POR ESTRELA | B26: =AVERAGE(B2:B23) -> 1.6666667 | C26: =AVERAGE(C2:C23) -> 1.0833333 | D26: =AVERAGE(D2:D23) -> 4.0833333 | E26: =AVERAGE(E2:E23) -> 9.5833333 | F26: =AVERAGE(F2:F23) -> 9.75 | G26: MÉDIA DAS ESTRELAS | H26: =SUM(B25*1,C25*2,D25*3,E25*4,F25*5)/H25 -> 3.9426752
G27: MÉDIA ANTERIOR | H27: ='SEMANA 21'!H26 -> 4.0116822 | I27: =_xlfn.CONCAT("", (H26-H27)/H27, "%") -> -0,0172015328172007%

Sheet SEMANA 23
B1: 🌟 | C1: 🌟🌟 | D1: 🌟🌟🌟 | E1: 🌟🌟🌟🌟 | F1: 🌟🌟🌟🌟🌟 | G1: TOTAL DE VOTOS / REFEIÇÃO | H1: TOTAL POR DIA
A2: Segunda (Almoço) | B2: 0 | C2: 0 | D2: 6 | E2: 17 | F2: 22 | G2: =SUM(B2:F2) -> 45 | H2: =SUM(G2:G5) -> 125
A3: Segunda (Almoço) #2 | B3: 1 | C3: 0 | D3: 4 | E3: 11 | F3: 6 | G3: =SUM(B3:F3) -> 22
A4: Segunda (Janta) | B4: 2 | C4: 5 | D4: 9 | E4: 11 | F4: 11 | G4: =SUM(B4:F4) -> 38
A5: Segunda (Janta) #2 | B5: 0 | C5: 1 | D5: 4 | E5: 3 | F5: 12 | G5: =SUM(B5:F5) -> 20
A6: Terça (Almoço) | B6: 0 | C6: 0 | D6: 16 | E6: 8 | F6: 17 | G6: =SUM(B6:F6) -> 41 | H6: =SUM(G6:G9) -> 122
A7: Terça (Almoço) #2 | B7: 1 | C7: 0 | D7: 2 | E7: 6 | F7: 14 | G7: =SUM(B7:F7) -> 23
A8: Terça (Janta) | B8: 24 | C8: 5 | D8: 2 | E8: 6 | F8: 5 | G8: =SUM(B8:F8) -> 42
A9: Terça (Janta) #2 | B9: 9 | C9: 0 | D9: 2 | E9: 1 | F9: 4 | G9: =SUM(B9:F9) -> 16
A10: Quarta (Almoço) | B10: 4 | C10: 12 | D10: 21 | E10: 8 | F10: 17 | G10: =SUM(B10:F10) -> 62 | H10: =SUM(G10:G13) -> 151
A11: Quarta (Almoço) #2 | B11: 2 | C11: 1 | D11: 8 | E11: 11 | F11: 3 | G11: =SUM(B11:F11) -> 25
A12: Quarta (Janta) | B12: 1 | C12: 1 | D12: 6 | E12: 13 | F12: 26 | G12: =SUM(B12:F12) -> 47
A13: Quarta (Janta) #2 | B13: 0 | C13: 0 | D13: 1 | E13: 9 | F13: 7 | G13: =SUM(B13:F13) -> 17
A14: Quinta (Almoço) | B14: 2 | C14: 0 | D14: 10 | E14: 11 | F14: 34 | G14: =SUM(B14:F14) -> 57 | H14: =SUM(G14:G17) -> 148
A15: Quinta (Almoço) #2 | B15: 0 | C15: 0 | D15: 7 | E15: 12 | F15: 13 | G15: =SUM(B15:F15) -> 32
A16: Quinta (Janta) | B16: 5 | C16: 4 | D16: 11 | E16: 18 | F16: 8 | G16: =SUM(B16:F16) -> 46
A17: Quinta (Janta) #2 | B17: 1 | C17: 2 | D17: 2 | E17: 3 | F17: 5 | G17: =SUM(B17:F17) -> 13
A18: Sexta (Almoço) | B18: 2 | C18: 3 | D18: 6 | E18: 11 | F18: 6 | G18: =SUM(B18:F18) -> 28 | H18: =SUM(G18:G21) -> 80
A19: Sexta (Almoço) #2 | B19: 0 | C19: 0 | D19: 4 | E19: 10 | F19: 5 | G19: =SUM(B19:F19) -> 19
A20: Sexta (Janta) | B20: 1 | C20: 0 | D20: 2 | E20: 3 | F20: 14 | G20: =SUM(B20:F20) -> 20
A21: Sexta (Janta) #2 | B21: 0 | C21: 0 | D21: 7 | E21: 0 | F21: 6 | G21: =SUM(B21:F21) -> 13
A22: Sábado | B22: 0 | C22: 0 | D22: 0 | E22: 9 | F22: 18 | G22: =SUM(B22:F22) -> 27 | H22: =SUM(G22:G24) -> 36
A23: Sábado #2 | B23: 0 | C23: 0 | D23: 2 | E23: 3 | F23: 4 | G23: =SUM(B23:F23) -> 9
A25: TOTAL DE ESTRELAS | B25: =SUM(B2:B23) -> 55 | C25: =SUM(C2:C23) -> 34 | D25: =SUM(D2:D23) -> 132 | E25: =SUM(E2:E23) -> 184 | F25: =SUM(F2:F23) -> 257 | G25: TOTAL DE VOTOS | H25: =SUM(G2:G23) -> 662
A26: MEDIA POR ESTRELA | B26: =AVERAGE(B2:B23) -> 2.5 | C26: =AVERAGE(C2:C23) -> 1.5454545 | D26: =AVERAGE(D2:D23) -> 6 | E26: =AVERAGE(E2:E23) -> 8.3636364 | F26: =AVERAGE(F2:F23) -> 11.681818 | G26: MÉDIA DAS ESTRELAS | H26: =SUM(B25*1,C25*2,D25*3,E25*4,F25*5)/H25 -> 3.836858
G27: MÉDIA ANTERIOR | H27: ='SEMANA 22'!H26 -> 3.9426752 | I27: =_xlfn.CONCAT("", (H26-H27)/H27, "%") -> -0,0268389225385453%

Sheet SEMANA 24
B1: 🌟 | C1: 🌟🌟 | D1: 🌟🌟🌟 | E1: 🌟🌟🌟🌟 | F1: 🌟🌟🌟🌟🌟 | G1: TOTAL DE VOTOS / REFEIÇÃO | H1: TOTAL POR DIA
A2: Segunda (Almoço) | B2: 1 | C2: 2 | D2: 12 | E2: 17 | F2: 17 | G2: =SUM(B2:F2) -> 49 | H2: =SUM(G2:G5) -> 106
A3: Segunda (Almoço) #2 | B3: 0 | C3: 0 | D3: 11 | E3: 11 | F3: 7 | G3: =SUM(B3:F3) -> 29
A4: Segunda (Janta) | B4: 2 | C4: 0 | D4: 1 | E4: 10 | F4: 15 | G4: =SUM(B4:F4) -> 28
A5: Segunda (Janta) #2 | G5: =SUM(B5:F5) -> 0
A6: Terça (Almoço) | B6: 1 | C6: 0 | D6: 3 | E6: 4 | F6: 21 | G6: =SUM(B6:F6) -> 29 | H6: =SUM(G6:G9) -> 120
A7: Terça (Almoço) #2 | B7: 0 | C7: 0 | D7: 1 | E7: 3 | F7: 20 | G7: =SUM(B7:F7) -> 24
A8: Terça (Janta) | B8: 9 | C8: 14 | D8: 7 | E8: 9 | F8: 11 | G8: =SUM(B8:F8) -> 50
A9: Terça (Janta) #2 | B9: 2 | C9: 9 | D9: 3 | E9: 1 | F9: 2 | G9: =SUM(B9:F9) -> 17
A10: Quarta (Almoço) | B10: 2 | C10: 1 | D10: 19 | E10: 22 | F10: 11 | G10: =SUM(B10:F10) -> 55 | H10: =SUM(G10:G13) -> 109
A11: Quarta (Almoço) #2 | B11: 0 | C11: 0 | D11: 6 | E11: 16 | F11: 7 | G11: =SUM(B11:F11) -> 29
A12: Quarta (Janta) | B12: 2 | C12: 1 | D12: 0 | E12: 3 | F12: 9 | G12: =SUM(B12:F12) -> 15
A13: Quarta (Janta) #2 | B13: 0 | C13: 0 | D13: 1 | E13: 2 | F13: 7 | G13: =SUM(B13:F13) -> 10
A14: Quinta (Almoço) | B14: 1 | C14: 3 | D14: 1 | E14: 3 | F14: 7 | G14: =SUM(B14:F14) -> 15 | H14: =SUM(G14:G17) -> 65
A15: Quinta (Almoço) #2 | B15: 0 | C15: 2 | D15: 3 | E15: 1 | F15: 3 | G15: =SUM(B15:F15) -> 9
A16: Quinta (Janta) | B16: 0 | C16: 0 | D16: 1 | E16: 2 | F16: 25 | G16: =SUM(B16:F16) -> 28
A17: Quinta (Janta) #2 | B17: 0 | C17: 0 | D17: 0 | E17: 1 | F17: 12 | G17: =SUM(B17:F17) -> 13
A18: Sexta (Almoço) | B18: 0 | C18: 0 | D18: 2 | E18: 7 | F18: 15 | G18: =SUM(B18:F18) -> 24 | H18: =SUM(G18:G21) -> 87
A19: Sexta (Almoço) #2 | B19: 0 | C19: 0 | D19: 7 | E19: 5 | F19: 8 | G19: =SUM(B19:F19) -> 20
A20: Sexta (Janta) | B20: 0 | C20: 0 | D20: 2 | E20: 3 | F20: 25 | G20: =SUM(B20:F20) -> 30
A21: Sexta (Janta) #2 | B21: 0 | C21: 0 | D21: 3 | E21: 3 | F21: 7 | G21: =SUM(B21:F21) -> 13
A22: Sábado | B22: 1 | C22: 6 | D22: 4 | E22: 11 | F22: 7 | G22: =SUM(B22:F22) -> 29 | H22: =SUM(G22:G24) -> 38
A23: Sábado #2 | B23: 0 | C23: 0 | D23: 0 | E23: 6 | F23: 3 | G23: =SUM(B23:F23) -> 9
A25: TOTAL DE ESTRELAS | B25: =SUM(B2:B23) -> 21 | C25: =SUM(C2:C23) -> 38 | D25: =SUM(D2:D23) -> 87 | E25: =SUM(E2:E23) -> 140 | F25: =SUM(F2:F23) -> 239 | G25: TOTAL DE VOTOS | H25: =SUM(G2:G23) -> 525
A26: MEDIA POR ESTRELA | B26: =AVERAGE(B2:B23) -> 1 | C26: =AVERAGE(C2:C23) -> 1.8095238 | D26: =AVERAGE(D2:D23) -> 4.1428571 | E26: =AVERAGE(E2:E23) -> 6.6666667 | F26: =AVERAGE(F2:F23) -> 11.380952 | G26: MÉDIA DAS ESTRELAS | H26: =SUM(B25*1,C25*2,D25*3,E25*4,F25*5)/H25 -> 4.0247619
G27: MÉDIA ANTERIOR | H27: ='SEMANA 23'!H26 -> 3.836858 | I27: =_xlfn.CONCAT("", (H26-H27)/H27, "%") -> 0,048973378327709%

Sheet SEMANA 25
B1: 🌟 | C1: 🌟🌟 | D1: 🌟🌟🌟 | E1: 🌟🌟🌟🌟 | F1: 🌟🌟🌟🌟🌟 | G1: TOTAL DE VOTOS / REFEIÇÃO | H1: TOTAL POR DIA
A2: Segunda (Almoço) | B2: 1 | C2: 1 | D2: 1 | E2: 4 | F2: 28 | G2: =SUM(B2:F2) -> 35 | H2: =SUM(G2:G5) -> 99
A3: Segunda (Almoço) #2 | B3: 0 | C3: 0 | D3: 1 | E3: 8 | F3: 1 | G3: =SUM(B3:F3) -> 10
A4: Segunda (Janta) | B4: 0 | C4: 0 | D4: 2 | E4: 13 | F4: 23 | G4: =SUM(B4:F4) -> 38
A5: Segunda (Janta) #2 | B5: 0 | C5: 0 | D5: 0 | E5: 5 | F5: 11 | G5: =SUM(B5:F5) -> 16
A6: Terça (Almoço) | B6: 0 | C6: 0 | D6: 3 | E6: 10 | F6: 28 | G6: =SUM(B6:F6) -> 41 | H6: =SUM(G6:G9) -> 95
A7: Terça (Almoço) #2 | B7: 0 | C7: 0 | D7: 1 | E7: 6 | F7: 4 | G7: =SUM(B7:F7) -> 11
A8: Terça (Janta) | B8: 0 | C8: 1 | D8: 0 | E8: 9 | F8: 23 | G8: =SUM(B8:F8) -> 33
A9: Terça (Janta) #2 | B9: 0 | C9: 0 | D9: 1 | E9: 3 | F9: 6 | G9: =SUM(B9:F9) -> 10
A10: Quarta (Almoço) | B10: 1 | C10: 0 | D10: 2 | E10: 9 | F10: 10 | G10: =SUM(B10:F10) -> 22 | H10: =SUM(G10:G13) -> 78
A11: Quarta (Almoço) #2 | B11: 0 | C11: 0 | D11: 0 | E11: 0 | F11: 9 | G11: =SUM(B11:F11) -> 9
A12: Quarta (Janta) | B12: 3 | C12: 0 | D12: 4 | E12: 4 | F12: 23 | G12: =SUM(B12:F12) -> 34
A13: Quarta (Janta) #2 | B13: 0 | C13: 0 | D13: 1 | E13: 2 | F13: 10 | G13: =SUM(B13:F13) -> 13
A14: Quinta (Almoço) | B14: 0 | C14: 4 | D14: 10 | E14: 9 | F14: 7 | G14: =SUM(B14:F14) -> 30 | H14: =SUM(G14:G17) -> 70
A15: Quinta (Almoço) #2 | B15: 1 | C15: 1 | D15: 1 | E15: 0 | F15: 4 | G15: =SUM(B15:F15) -> 7
A16: Quinta (Janta) | B16: 0 | C16: 2 | D16: 3 | E16: 7 | F16: 13 | G16: =SUM(B16:F16) -> 25
A17: Quinta (Janta) #2 | B17: 0 | C17: 0 | D17: 0 | E17: 5 | F17: 3 | G17: =SUM(B17:F17) -> 8
A18: Sexta (Almoço) | B18: 0 | C18: 2 | D18: 3 | E18: 10 | F18: 7 | G18: =SUM(B18:F18) -> 22 | H18: =SUM(G18:G21) -> 61
A19: Sexta (Almoço) #2 | B19: 0 | C19: 0 | D19: 1 | E19: 2 | F19: 9 | G19: =SUM(B19:F19) -> 12
A20: Sexta (Janta) | B20: 1 | C20: 0 | D20: 0 | E20: 2 | F20: 15 | G20: =SUM(B20:F20) -> 18
A21: Sexta (Janta) #2 | B21: 0 | C21: 0 | D21: 1 | E21: 2 | F21: 6 | G21: =SUM(B21:F21) -> 9
A22: Sábado | B22: 0 | C22: 0 | D22: 0 | E22: 0 | F22: 10 | G22: =SUM(B22:F22) -> 10 | H22: =SUM(G22:G24) -> 20
A23: Sábado #2 | B23: 1 | C23: 0 | D23: 0 | E23: 6 | F23: 3 | G23: =SUM(B23:F23) -> 10
A25: TOTAL DE ESTRELAS | B25: =SUM(B2:B23) -> 8 | C25: =SUM(C2:C23) -> 11 | D25: =SUM(D2:D23) -> 35 | E25: =SUM(E2:E23) -> 116 | F25: =SUM(F2:F23) -> 253 | G25: TOTAL DE VOTOS | H25: =SUM(G2:G23) -> 423
A26: MEDIA POR ESTRELA | B26: =AVERAGE(B2:B23) -> 0.36363636 | C26: =AVERAGE(C2:C23) -> 0.5 | D26: =AVERAGE(D2:D23) -> 1.5909091 | E26: =AVERAGE(E2:E23) -> 5.2727273 | F26: =AVERAGE(F2:F23) -> 11.5 | G26: MÉDIA DAS ESTRELAS | H26: =SUM(B25*1,C25*2,D25*3,E25*4,F25*5)/H25 -> 4.4066194
G27: MÉDIA ANTERIOR | H27: ='SEMANA 24'!H26 -> 4.0247619 | I27: =_xlfn.CONCAT("", (H26-H27)/H27, "%") -> 0,0948770361121462%

Sheet SEMANA 26
B1: 🌟 | C1: 🌟🌟 | D1: 🌟🌟🌟 | E1: 🌟🌟🌟🌟 | F1: 🌟🌟🌟🌟🌟 | G1: TOTAL DE VOTOS / REFEIÇÃO | H1: TOTAL POR DIA
A2: Segunda (Almoço) | B2: 0 | C2: 1 | D2: 4 | E2: 13 | F2: 14 | G2: =SUM(B2:F2) -> 32 | H2: =SUM(G2:G5) -> 44
A3: Segunda (Almoço) #2 | B3: 0 | C3: 2 | D3: 1 | E3: 9 | F3: 0 | G3: =SUM(B3:F3) -> 12
A4: Segunda (Janta) | B4: 0 | C4: 0 | D4: 0 | E4: 0 | F4: 0 | G4: =SUM(B4:F4) -> 0
A5: Segunda (Janta) #2 | B5: 0 | C5: 0 | D5: 0 | E5: 0 | F5: 0 | G5: =SUM(B5:F5) -> 0
A6: Terça (Almoço) | B6: 0 | C6: 2 | D6: 3 | E6: 15 | F6: 4 | G6: =SUM(B6:F6) -> 24 | H6: =SUM(G6:G9) -> 35
A7: Terça (Almoço) #2 | B7: 0 | C7: 0 | D7: 1 | E7: 5 | F7: 5 | G7: =SUM(B7:F7) -> 11
A8: Terça (Janta) | B8: 0 | C8: 0 | D8: 0 | E8: 0 | F8: 0 | G8: =SUM(B8:F8) -> 0
A9: Terça (Janta) #2 | B9: 0 | C9: 0 | D9: 0 | E9: 0 | F9: 0 | G9: =SUM(B9:F9) -> 0
A10: Quarta (Almoço) | B10: 0 | C10: 0 | D10: 2 | E10: 9 | F10: 20 | G10: =SUM(B10:F10) -> 31 | H10: =SUM(G10:G13) -> 82
A11: Quarta (Almoço) #2 | B11: 0 | C11: 0 | D11: 0 | E11: 3 | F11: 9 | G11: =SUM(B11:F11) -> 12
A12: Quarta (Janta) | B12: 0 | C12: 0 | D12: 10 | E12: 8 | F12: 6 | G12: =SUM(B12:F12) -> 24
A13: Quarta (Janta) #2 | B13: 0 | C13: 0 | D13: 2 | E13: 2 | F13: 11 | G13: =SUM(B13:F13) -> 15
A14: Quinta (Almoço) | B14: 0 | C14: 0 | D14: 7 | E14: 4 | F14: 4 | G14: =SUM(B14:F14) -> 15 | H14: =SUM(G14:G17) -> 50
A15: Quinta (Almoço) #2 | B15: 0 | C15: 0 | D15: 0 | E15: 4 | F15: 3 | G15: =SUM(B15:F15) -> 7
A16: Quinta (Janta) | B16: 1 | C16: 0 | D16: 5 | E16: 6 | F16: 9 | G16: =SUM(B16:F16) -> 21
A17: Quinta (Janta) #2 | B17: 0 | C17: 0 | D17: 1 | E17: 1 | F17: 5 | G17: =SUM(B17:F17) -> 7
A18: Sexta (Almoço) | B18: 0 | C18: 0 | D18: 0 | E18: 6 | F18: 19 | G18: =SUM(B18:F18) -> 25 | H18: =SUM(G18:G21) -> 55
A19: Sexta (Almoço) #2 | B19: 0 | C19: 0 | D19: 0 | E19: 3 | F19: 3 | G19: =SUM(B19:F19) -> 6
A20: Sexta (Janta) | B20: 1 | C20: 4 | D20: 3 | E20: 4 | F20: 3 | G20: =SUM(B20:F20) -> 15
A21: Sexta (Janta) #2 | B21: 1 | C21: 0 | D21: 0 | E21: 2 | F21: 6 | G21: =SUM(B21:F21) -> 9
A22: Sábado | B22: 1 | C22: 5 | D22: 3 | E22: 3 | F22: 0 | G22: =SUM(B22:F22) -> 12 | H22: =SUM(G22:G24) -> 16
A23: Sábado #2 | B23: 0 | C23: 0 | D23: 0 | E23: 3 | F23: 1 | G23: =SUM(B23:F23) -> 4
A25: TOTAL DE ESTRELAS | B25: =SUM(B2:B23) -> 4 | C25: =SUM(C2:C23) -> 14 | D25: =SUM(D2:D23) -> 42 | E25: =SUM(E2:E23) -> 100 | F25: =SUM(F2:F23) -> 122 | G25: TOTAL DE VOTOS | H25: =SUM(G2:G23) -> 282
A26: MEDIA POR ESTRELA | B26: =AVERAGE(B2:B23) -> 0.18181818 | C26: =AVERAGE(C2:C23) -> 0.63636364 | D26: =AVERAGE(D2:D23) -> 1.9090909 | E26: =AVERAGE(E2:E23) -> 4.5454545 | F26: =AVERAGE(F2:F23) -> 5.5454545 | G26: MÉDIA DAS ESTRELAS | H26: =SUM(B25*1,C25*2,D25*3,E25*4,F25*5)/H25 -> 4.141844
G27: MÉDIA ANTERIOR | H27: ='SEMANA 25'!H26 -> 4.4066194 | I27: =_xlfn.CONCAT("", (H26-H27)/H27, "%") -> -0,0600858369098713%

Sheet SEMANA 27
B1: 🌟 | C1: 🌟🌟 | D1: 🌟🌟🌟 | E1: 🌟🌟🌟🌟 | F1: 🌟🌟🌟🌟🌟 | G1: TOTAL DE VOTOS / REFEIÇÃO | H1: TOTAL POR DIA
A2: Segunda (Almoço) | B2: 1 | C2: 0 | D2: 6 | E2: 9 | F2: 10 | G2: =SUM(B2:F2) -> 26 | H2: =SUM(G2:G5) -> 35
A3: Segunda (Almoço) #2 | B3: 1 | C3: 0 | D3: 0 | E3: 4 | F3: 4 | G3: =SUM(B3:F3) -> 9
A4: Segunda (Janta) | B4: 0 | C4: 0 | D4: 0 | E4: 0 | F4: 0 | G4: =SUM(B4:F4) -> 0
A5: Segunda (Janta) #2 | B5: 0 | C5: 0 | D5: 0 | E5: 0 | F5: 0 | G5: =SUM(B5:F5) -> 0
A6: Terça (Almoço) | B6: 1 | C6: 1 | D6: 6 | E6: 9 | F6: 3 | G6: =SUM(B6:F6) -> 20 | H6: =SUM(G6:G9) -> 59
A7: Terça (Almoço) #2 | B7: 1 | C7: 0 | D7: 2 | E7: 1 | F7: 4 | G7: =SUM(B7:F7) -> 8
A8: Terça (Janta) | B8: 1 | C8: 1 | D8: 2 | E8: 6 | F8: 11 | G8: =SUM(B8:F8) -> 21
A9: Terça (Janta) #2 | B9: 2 | C9: 0 | D9: 0 | E9: 3 | F9: 5 | G9: =SUM(B9:F9) -> 10
A10: Quarta (Almoço) | B10: 2 | C10: 1 | D10: 1 | E10: 3 | F10: 6 | G10: =SUM(B10:F10) -> 13 | H10: =SUM(G10:G13) -> 57
A11: Quarta (Almoço) #2 | B11: 0 | C11: 1 | D11: 0 | E11: 4 | F11: 6 | G11: =SUM(B11:F11) -> 11
A12: Quarta (Janta) | B12: 0 | C12: 1 | D12: 6 | E12: 15 | F12: 3 | G12: =SUM(B12:F12) -> 25
A13: Quarta (Janta) #2 | B13: 0 | C13: 0 | D13: 3 | E13: 1 | F13: 4 | G13: =SUM(B13:F13) -> 8
A14: Quinta (Almoço) | B14: 1 | C14: 2 | D14: 6 | E14: 6 | F14: 4 | G14: =SUM(B14:F14) -> 19 | H14: =SUM(G14:G17) -> 61
A15: Quinta (Almoço) #2 | B15: 0 | C15: 0 | D15: 2 | E15: 1 | F15: 1 | G15: =SUM(B15:F15) -> 4
A16: Quinta (Janta) | B16: 1 | C16: 0 | D16: 3 | E16: 3 | F16: 20 | G16: =SUM(B16:F16) -> 27
A17: Quinta (Janta) #2 | B17: 0 | C17: 1 | D17: 0 | E17: 4 | F17: 6 | G17: =SUM(B17:F17) -> 11
A18: Sexta (Almoço) | B18: 0 | C18: 0 | D18: 4 | E18: 4 | F18: 13 | G18: =SUM(B18:F18) -> 21 | H18: =SUM(G18:G21) -> 53
A19: Sexta (Almoço) #2 | B19: 0 | C19: 0 | D19: 4 | E19: 0 | F19: 1 | G19: =SUM(B19:F19) -> 5
A20: Sexta (Janta) | B20: 0 | C20: 0 | D20: 5 | E20: 6 | F20: 3 | G20: =SUM(B20:F20) -> 14
A21: Sexta (Janta) #2 | B21: 0 | C21: 1 | D21: 1 | E21: 3 | F21: 8 | G21: =SUM(B21:F21) -> 13
A22: Sábado | B22: 0 | C22: 0 | D22: 0 | E22: 6 | F22: 6 | G22: =SUM(B22:F22) -> 12 | H22: =SUM(G22:G24) -> 20
A23: Sábado #2 | B23: 0 | C23: 1 | D23: 1 | E23: 2 | F23: 4 | G23: =SUM(B23:F23) -> 8
A25: TOTAL DE ESTRELAS | B25: =SUM(B2:B23) -> 11 | C25: =SUM(C2:C23) -> 10 | D25: =SUM(D2:D23) -> 52 | E25: =SUM(E2:E23) -> 90 | F25: =SUM(F2:F23) -> 122 | G25: TOTAL DE VOTOS | H25: =SUM(G2:G23) -> 285
A26: MEDIA POR ESTRELA | B26: =AVERAGE(B2:B23) -> 0.5 | C26: =AVERAGE(C2:C23) -> 0.45454545 | D26: =AVERAGE(D2:D23) -> 2.3636364 | E26: =AVERAGE(E2:E23) -> 4.0909091 | F26: =AVERAGE(F2:F23) -> 5.5454545 | G26: MÉDIA DAS ESTRELAS | H26: =SUM(B25*1,C25*2,D25*3,E25*4,F25*5)/H25 -> 4.0596491
G27: MÉDIA ANTERIOR | H27: ='SEMANA 26'!H26 -> 4.141844 | I27: =_xlfn.CONCAT("", (H26-H27)/H27, "%") -> -0,019844989185292%

Sheet SEMANA 28
B1: 🌟 | C1: 🌟🌟 | D1: 🌟🌟🌟 | E1: 🌟🌟🌟🌟 | F1: 🌟🌟🌟🌟🌟 | G1: TOTAL DE VOTOS / REFEIÇÃO | H1: TOTAL POR DIA
A2: Segunda (Almoço) | B2: 0 | C2: 1 | D2: 9 | E2: 11 | F2: 2 | G2: =SUM(B2:F2) -> 23 | H2: =SUM(G2:G5) -> 32
A3: Segunda (Almoço) #2 | B3: 4 | C3: 0 | D3: 2 | E3: 0 | F3: 3 | G3: =SUM(B3:F3) -> 9
A4: Segunda (Janta) | B4: 0 | C4: 0 | D4: 0 | E4: 0 | F4: 0 | G4: =SUM(B4:F4) -> 0
A5: Segunda (Janta) #2 | B5: 0 | C5: 0 | D5: 0 | E5: 0 | F5: 0 | G5: =SUM(B5:F5) -> 0
A6: Terça (Almoço) | B6: 3 | C6: 1 | D6: 3 | E6: 15 | F6: 2 | G6: =SUM(B6:F6) -> 24 | H6: =SUM(G6:G9) -> 60
A7: Terça (Almoço) #2 | B7: 0 | C7: 0 | D7: 2 | E7: 4 | F7: 4 | G7: =SUM(B7:F7) -> 10
A8: Terça (Janta) | B8: 0 | C8: 3 | D8: 1 | E8: 4 | F8: 10 | G8: =SUM(B8:F8) -> 18
A9: Terça (Janta) #2 | B9: 0 | C9: 0 | D9: 2 | E9: 2 | F9: 4 | G9: =SUM(B9:F9) -> 8
A10: Quarta (Almoço) | B10: 0 | C10: 2 | D10: 4 | E10: 6 | F10: 5 | G10: =SUM(B10:F10) -> 17 | H10: =SUM(G10:G13) -> 40
A11: Quarta (Almoço) #2 | B11: 0 | C11: 3 | D11: 0 | E11: 1 | F11: 2 | G11: =SUM(B11:F11) -> 6
A12: Quarta (Janta) | B12: 0 | C12: 2 | D12: 2 | E12: 7 | F12: 0 | G12: =SUM(B12:F12) -> 11
A13: Quarta (Janta) #2 | B13: 0 | C13: 2 | D13: 1 | E13: 1 | F13: 2 | G13: =SUM(B13:F13) -> 6
A14: Quinta (Almoço) | B14: 1 | C14: 0 | D14: 1 | E14: 3 | F14: 10 | G14: =SUM(B14:F14) -> 15 | H14: =SUM(G14:G17) -> 50
A15: Quinta (Almoço) #2 | B15: 2 | C15: 0 | D15: 1 | E15: 4 | F15: 9 | G15: =SUM(B15:F15) -> 16
A16: Quinta (Janta) | B16: 0 | C16: 0 | D16: 1 | E16: 6 | F16: 5 | G16: =SUM(B16:F16) -> 12
A17: Quinta (Janta) #2 | B17: 0 | C17: 0 | D17: 0 | E17: 3 | F17: 4 | G17: =SUM(B17:F17) -> 7
A18: Sexta (Almoço) | B18: 0 | C18: 3 | D18: 5 | E18: 0 | F18: 0 | G18: =SUM(B18:F18) -> 8 | H18: =SUM(G18:G21) -> 34
A19: Sexta (Almoço) #2 | B19: 0 | C19: 0 | D19: 7 | E19: 3 | F19: 0 | G19: =SUM(B19:F19) -> 10
A20: Sexta (Janta) | B20: 0 | C20: 3 | D20: 1 | E20: 5 | F20: 3 | G20: =SUM(B20:F20) -> 12
A21: Sexta (Janta) #2 | B21: 1 | C21: 0 | D21: 0 | E21: 2 | F21: 1 | G21: =SUM(B21:F21) -> 4
A22: Sábado | B22: 0 | C22: 2 | D22: 8 | E22: 1 | F22: 2 | G22: =SUM(B22:F22) -> 13 | H22: =SUM(G22:G24) -> 16
A23: Sábado #2 | B23: 0 | C23: 0 | D23: 0 | E23: 1 | F23: 2 | G23: =SUM(B23:F23) -> 3
A25: TOTAL DE ESTRELAS | B25: =SUM(B2:B23) -> 11 | C25: =SUM(C2:C23) -> 22 | D25: =SUM(D2:D23) -> 50 | E25: =SUM(E2:E23) -> 79 | F25: =SUM(F2:F23) -> 70 | G25: TOTAL DE VOTOS | H25: =SUM(G2:G23) -> 232
A26: MEDIA POR ESTRELA | B26: =AVERAGE(B2:B23) -> 0.5 | C26: =AVERAGE(C2:C23) -> 1 | D26: =AVERAGE(D2:D23) -> 2.2727273 | E26: =AVERAGE(E2:E23) -> 3.5909091 | F26: =AVERAGE(F2:F23) -> 3.1818182 | G26: MÉDIA DAS ESTRELAS | H26: =SUM(B25*1,C25*2,D25*3,E25*4,F25*5)/H25 -> 3.7543103
G27: MÉDIA ANTERIOR | H27: ='SEMANA 27'!H26 -> 4.0596491 | I27: =_xlfn.CONCAT("", (H26-H27)/H27, "%") -> -0,0752130956993413%

Sheet SEMANA 29
B1: 🌟 | C1: 🌟🌟 | D1: 🌟🌟🌟 | E1: 🌟🌟🌟🌟 | F1: 🌟🌟🌟🌟🌟 | G1: TOTAL DE VOTOS / REFEIÇÃO | H1: TOTAL POR DIA
A2: Segunda (Almoço) | B2: 0 | C2: 2 | D2: 2 | E2: 13 | F2: 2 | G2: =SUM(B2:F2) -> 19 | H2: =SUM(G2:G5) -> 44
A3: Segunda (Almoço) #2 | B3: 0 | C3: 0 | D3: 0 | E3: 3 | F3: 1 | G3: =SUM(B3:F3) -> 4
A4: Segunda (Janta) | B4: 0 | C4: 0 | D4: 4 | E4: 7 | F4: 3 | G4: =SUM(B4:F4) -> 14
A5: Segunda (Janta) #2 | B5: 0 | C5: 0 | D5: 2 | E5: 2 | F5: 3 | G5: =SUM(B5:F5) -> 7
A6: Terça (Almoço) | B6: 0 | C6: 0 | D6: 0 | E6: 0 | F6: 0 | G6: =SUM(B6:F6) -> 0 | H6: =SUM(G6:G9) -> 0
A7: Terça (Almoço) #2 | G7: =SUM(B7:F7) -> 0
A8: Terça (Janta) | B8: 0 | C8: 0 | D8: 0 | E8: 0 | F8: 0 | G8: =SUM(B8:F8) -> 0
A9: Terça (Janta) #2 | G9: =SUM(B9:F9) -> 0
A10: Quarta (Almoço) | B10: 0 | C10: 1 | D10: 2 | E10: 7 | F10: 5 | G10: =SUM(B10:F10) -> 15 | H10: =SUM(G10:G13) -> 37
A11: Quarta (Almoço) #2 | B11: 1 | C11: 0 | D11: 0 | E11: 3 | F11: 1 | G11: =SUM(B11:F11) -> 5
A12: Quarta (Janta) | B12: 2 | C12: 0 | D12: 0 | E12: 4 | F12: 4 | G12: =SUM(B12:F12) -> 10
A13: Quarta (Janta) #2 | B13: 0 | C13: 0 | D13: 0 | E13: 0 | F13: 7 | G13: =SUM(B13:F13) -> 7
A14: Quinta (Almoço) | B14: 0 | C14: 0 | D14: 2 | E14: 4 | F14: 10 | G14: =SUM(B14:F14) -> 16 | H14: =SUM(G14:G17) -> 18
A15: Quinta (Almoço) #2 | B15: 0 | C15: 0 | D15: 0 | E15: 0 | F15: 2 | G15: =SUM(B15:F15) -> 2
A16: Quinta (Janta) | B16: 0 | C16: 0 | D16: 0 | E16: 0 | F16: 0 | G16: =SUM(B16:F16) -> 0
A17: Quinta (Janta) #2 | G17: =SUM(B17:F17) -> 0
A18: Sexta (Almoço) | B18: 1 | C18: 0 | D18: 2 | E18: 9 | F18: 14 | G18: =SUM(B18:F18) -> 26 | H18: =SUM(G18:G21) -> 53
A19: Sexta (Almoço) #2 | B19: 1 | C19: 0 | D19: 0 | E19: 4 | F19: 5 | G19: =SUM(B19:F19) -> 10
A20: Sexta (Janta) | B20: 0 | C20: 2 | D20: 0 | E20: 2 | F20: 8 | G20: =SUM(B20:F20) -> 12
A21: Sexta (Janta) #2 | B21: 0 | C21: 1 | D21: 0 | E21: 3 | F21: 1 | G21: =SUM(B21:F21) -> 5
A22: Sábado | B22: 1 | C22: 1 | D22: 0 | E22: 2 | F22: 8 | G22: =SUM(B22:F22) -> 12 | H22: =SUM(G22:G24) -> 15
A23: Sábado #2 | B23: 0 | C23: 0 | D23: 0 | E23: 1 | F23: 2 | G23: =SUM(B23:F23) -> 3
A25: TOTAL DE ESTRELAS | B25: =SUM(B2:B23) -> 6 | C25: =SUM(C2:C23) -> 7 | D25: =SUM(D2:D23) -> 14 | E25: =SUM(E2:E23) -> 64 | F25: =SUM(F2:F23) -> 76 | G25: TOTAL DE VOTOS | H25: =SUM(G2:G23) -> 167
A26: MEDIA POR ESTRELA | B26: =AVERAGE(B2:B23) -> 0.31578947 | C26: =AVERAGE(C2:C23) -> 0.36842105 | D26: =AVERAGE(D2:D23) -> 0.73684211 | E26: =AVERAGE(E2:E23) -> 3.3684211 | F26: =AVERAGE(F2:F23) -> 4 | G26: MÉDIA DAS ESTRELAS | H26: =SUM(B25*1,C25*2,D25*3,E25*4,F25*5)/H25 -> 4.1796407
G27: MÉDIA ANTERIOR | H27: ='SEMANA 28'!H26 -> 3.7543103 | I27: =_xlfn.CONCAT("", (H26-H27)/H27, "%") -> 0,113291213210777%

Sheet SEMANA 31
B1: 🌟 | C1: 🌟🌟 | D1: 🌟🌟🌟 | E1: 🌟🌟🌟🌟 | F1: 🌟🌟🌟🌟🌟 | G1: TOTAL DE VOTOS / REFEIÇÃO | H1: TOTAL POR DIA
A2: Segunda (Almoço) | B2: 6 | C2: 2 | D2: 1 | E2: 7 | F2: 2 | G2: =SUM(B2:F2) -> 18 | H2: =SUM(G2:G5) -> 54
A3: Segunda (Almoço) #2 | B3: 0 | C3: 0 | D3: 2 | E3: 4 | F3: 1 | G3: =SUM(B3:F3) -> 7
A4: Segunda (Janta) | B4: 0 | C4: 1 | D4: 9 | E4: 7 | F4: 3 | G4: =SUM(B4:F4) -> 20
A5: Segunda (Janta) #2 | B5: 0 | C5: 1 | D5: 2 | E5: 5 | F5: 1 | G5: =SUM(B5:F5) -> 9
A6: Terça (Almoço) | B6: 0 | C6: 0 | D6: 0 | E6: 0 | F6: 0 | G6: =SUM(B6:F6) -> 0 | H6: =SUM(G6:G9) -> 39
A7: Terça (Almoço) #2 | G7: =SUM(B7:F7) -> 0
A8: Terça (Janta) | B8: 3 | C8: 5 | D8: 9 | E8: 9 | F8: 6 | G8: =SUM(B8:F8) -> 32
A9: Terça (Janta) #2 | B9: 0 | C9: 1 | D9: 3 | E9: 0 | F9: 3 | G9: =SUM(B9:F9) -> 7
A10: Quarta (Almoço) | B10: 0 | C10: 2 | D10: 4 | E10: 11 | F10: 0 | G10: =SUM(B10:F10) -> 17 | H10: =SUM(G10:G13) -> 55
A11: Quarta (Almoço) #2 | B11: 0 | C11: 2 | D11: 0 | E11: 2 | F11: 2 | G11: =SUM(B11:F11) -> 6
A12: Quarta (Janta) | B12: 0 | C12: 2 | D12: 8 | E12: 7 | F12: 6 | G12: =SUM(B12:F12) -> 23
A13: Quarta (Janta) #2 | B13: 0 | C13: 1 | D13: 0 | E13: 2 | F13: 6 | G13: =SUM(B13:F13) -> 9
A14: Quinta (Almoço) | B14: 0 | C14: 0 | D14: 3 | E14: 7 | F14: 4 | G14: =SUM(B14:F14) -> 14 | H14: =SUM(G14:G17) -> 32
A15: Quinta (Almoço) #2 | B15: 0 | C15: 0 | D15: 1 | E15: 2 | F15: 2 | G15: =SUM(B15:F15) -> 5
A16: Quinta (Janta) | B16: 0 | C16: 0 | D16: 0 | E16: 5 | F16: 4 | G16: =SUM(B16:F16) -> 9
A17: Quinta (Janta) #2 | B17: 0 | C17: 0 | D17: 0 | E17: 2 | F17: 2 | G17: =SUM(B17:F17) -> 4
A18: Sexta (Almoço) | B18: 0 | C18: 1 | D18: 7 | E18: 1 | F18: 4 | G18: =SUM(B18:F18) -> 13 | H18: =SUM(G18:G21) -> 34
A19: Sexta (Almoço) #2 | B19: 0 | C19: 0 | D19: 0 | E19: 2 | F19: 3 | G19: =SUM(B19:F19) -> 5
A20: Sexta (Janta) | B20: 3 | C20: 0 | D20: 4 | E20: 6 | F20: 0 | G20: =SUM(B20:F20) -> 13
A21: Sexta (Janta) #2 | B21: 0 | C21: 0 | D21: 0 | E21: 3 | F21: 0 | G21: =SUM(B21:F21) -> 3
A22: Sábado | B22: 1 | C22: 0 | D22: 5 | E22: 2 | F22: 4 | G22: =SUM(B22:F22) -> 12 | H22: =SUM(G22:G24) -> 14
A23: Sábado #2 | B23: 0 | C23: 0 | D23: 0 | E23: 1 | F23: 1 | G23: =SUM(B23:F23) -> 2
A25: TOTAL DE ESTRELAS | B25: =SUM(B2:B23) -> 13 | C25: =SUM(C2:C23) -> 18 | D25: =SUM(D2:D23) -> 58 | E25: =SUM(E2:E23) -> 85 | F25: =SUM(F2:F23) -> 54 | G25: TOTAL DE VOTOS | H25: =SUM(G2:G23) -> 228
A26: MEDIA POR ESTRELA | B26: =AVERAGE(B2:B23) -> 0.61904762 | C26: =AVERAGE(C2:C23) -> 0.85714286 | D26: =AVERAGE(D2:D23) -> 2.7619048 | E26: =AVERAGE(E2:E23) -> 4.047619 | F26: =AVERAGE(F2:F23) -> 2.5714286 | G26: MÉDIA DAS ESTRELAS | H26: =SUM(B25*1,C25*2,D25*3,E25*4,F25*5)/H25 -> 3.6535088
G27: MÉDIA ANTERIOR | H27: ='SEMANA 29'!H26 -> 4.1796407 | I27: =_xlfn.CONCAT("", (H26-H27)/H27, "%") -> -0,125879706429397%

Sheet SEMANA 32
B1: 🌟 | C1: 🌟🌟 | D1: 🌟🌟🌟 | E1: 🌟🌟🌟🌟 | F1: 🌟🌟🌟🌟🌟 | G1: TOTAL DE VOTOS / REFEIÇÃO | H1: TOTAL POR DIA
A2: Segunda (Almoço) | B2: 2 | C2: 0 | D2: 3 | E2: 35 | F2: 9 | G2: =SUM(B2:F2) -> 49 | H2: =SUM(G2:G5) -> 139
A3: Segunda (Almoço) #2 | B3: 0 | C3: 2 | D3: 0 | E3: 10 | F3: 29 | G3: =SUM(B3:F3) -> 41
A4: Segunda (Janta) | B4: 1 | C4: 6 | D4: 2 | E4: 1 | F4: 10 | G4: =SUM(B4:F4) -> 20
A5: Segunda (Janta) #2 | B5: 7 | C5: 2 | D5: 1 | E5: 15 | F5: 4 | G5: =SUM(B5:F5) -> 29
A6: Terça (Almoço) | B6: 15 | C6: 1 | D6: 8 | E6: 15 | F6: 7 | G6: =SUM(B6:F6) -> 46 | H6: =SUM(G6:G9) -> 113
A7: Terça (Almoço) #2 | B7: 1 | C7: 1 | D7: 11 | E7: 10 | F7: 4 | G7: =SUM(B7:F7) -> 27
A8: Terça (Janta) | B8: 2 | C8: 2 | D8: 4 | E8: 3 | F8: 12 | G8: =SUM(B8:F8) -> 23
A9: Terça (Janta) #2 | B9: 0 | C9: 1 | D9: 9 | E9: 4 | F9: 3 | G9: =SUM(B9:F9) -> 17
A10: Quarta (Almoço) | B10: 2 | C10: 7 | D10: 20 | E10: 7 | F10: 6 | G10: =SUM(B10:F10) -> 42 | H10: =SUM(G10:G13) -> 134
A11: Quarta (Almoço) #2 | B11: 0 | C11: 0 | D11: 5 | E11: 15 | F11: 10 | G11: =SUM(B11:F11) -> 30
A12: Quarta (Janta) | B12: 0 | C12: 2 | D12: 2 | E12: 7 | F12: 30 | G12: =SUM(B12:F12) -> 41
A13: Quarta (Janta) #2 | B13: 0 | C13: 1 | D13: 5 | E13: 9 | F13: 6 | G13: =SUM(B13:F13) -> 21
A14: Quinta (Almoço) | B14: 1 | C14: 0 | D14: 4 | E14: 10 | F14: 6 | G14: =SUM(B14:F14) -> 21 | H14: =SUM(G14:G17) -> 69
A15: Quinta (Almoço) #2 | B15: 0 | C15: 4 | D15: 4 | E15: 6 | F15: 0 | G15: =SUM(B15:F15) -> 14
A16: Quinta (Janta) | B16: 16 | C16: 3 | D16: 5 | E16: 0 | F16: 1 | G16: =SUM(B16:F16) -> 25
A17: Quinta (Janta) #2 | B17: 3 | C17: 0 | D17: 0 | E17: 4 | F17: 2 | G17: =SUM(B17:F17) -> 9
A18: Sexta (Almoço) | B18: 0 | C18: 3 | D18: 7 | E18: 14 | F18: 9 | G18: =SUM(B18:F18) -> 33 | H18: =SUM(G18:G21) -> 93
A19: Sexta (Almoço) #2 | B19: 0 | C19: 0 | D19: 1 | E19: 9 | F19: 6 | G19: =SUM(B19:F19) -> 16
A20: Sexta (Janta) | B20: 0 | C20: 0 | D20: 1 | E20: 6 | F20: 18 | G20: =SUM(B20:F20) -> 25
A21: Sexta (Janta) #2 | B21: 0 | C21: 0 | D21: 0 | E21: 1 | F21: 18 | G21: =SUM(B21:F21) -> 19
A22: Sábado | B22: 0 | C22: 1 | D22: 0 | E22: 4 | F22: 11 | G22: =SUM(B22:F22) -> 16 | H22: =SUM(G22:G24) -> 28
A23: Sábado #2 | B23: 0 | C23: 0 | D23: 1 | E23: 3 | F23: 8 | G23: =SUM(B23:F23) -> 12
A25: TOTAL DE ESTRELAS | B25: =SUM(B2:B23) -> 50 | C25: =SUM(C2:C23) -> 36 | D25: =SUM(D2:D23) -> 93 | E25: =SUM(E2:E23) -> 188 | F25: =SUM(F2:F23) -> 209 | G25: TOTAL DE VOTOS | H25: =SUM(G2:G23) -> 576
A26: MEDIA POR ESTRELA | B26: =AVERAGE(B2:B23) -> 2.2727273 | C26: =AVERAGE(C2:C23) -> 1.6363636 | D26: =AVERAGE(D2:D23) -> 4.2272727 | E26: =AVERAGE(E2:E23) -> 8.5454545 | F26: =AVERAGE(F2:F23) -> 9.5 | G26: MÉDIA DAS ESTRELAS | H26: =SUM(B25*1,C25*2,D25*3,E25*4,F25*5)/H25 -> 3.8159722
G27: MÉDIA ANTERIOR | H27: ='SEMANA 31'!H26 -> 3.6535088 | I27: =_xlfn.CONCAT("", (H26-H27)/H27, "%") -> 0,044467787114846%

Sheet SEMANA 33
B1: 🌟 | C1: 🌟🌟 | D1: 🌟🌟🌟 | E1: 🌟🌟🌟🌟 | F1: 🌟🌟🌟🌟🌟 | G1: TOTAL DE VOTOS / REFEIÇÃO | H1: TOTAL POR DIA
A2: Segunda (Almoço) | B2: 0 | C2: 4 | D2: 6 | E2: 7 | F2: 10 | G2: =SUM(B2:F2) -> 27 | H2: =SUM(G2:G5) -> 97
A3: Segunda (Almoço) #2 | B3: 1 | C3: 0 | D3: 3 | E3: 10 | F3: 11 | G3: =SUM(B3:F3) -> 25
A4: Segunda (Janta) | B4: 1 | C4: 0 | D4: 4 | E4: 11 | F4: 7 | G4: =SUM(B4:F4) -> 23
A5: Segunda (Janta) #2 | B5: 0 | C5: 0 | D5: 2 | E5: 10 | F5: 10 | G5: =SUM(B5:F5) -> 22
A6: Terça (Almoço) | B6: 1 | C6: 0 | D6: 4 | E6: 3 | F6: 8 | G6: =SUM(B6:F6) -> 16 | H6: =SUM(G6:G9) -> 99
A7: Terça (Almoço) #2 | B7: 0 | C7: 1 | D7: 3 | E7: 15 | F7: 7 | G7: =SUM(B7:F7) -> 26
A8: Terça (Janta) | B8: 1 | C8: 0 | D8: 1 | E8: 10 | F8: 16 | G8: =SUM(B8:F8) -> 28
A9: Terça (Janta) #2 | B9: 1 | C9: 0 | D9: 1 | E9: 8 | F9: 19 | G9: =SUM(B9:F9) -> 29
A10: Quarta (Almoço) | B10: 1 | C10: 3 | D10: 3 | E10: 4 | F10: 10 | G10: =SUM(B10:F10) -> 21 | H10: =SUM(G10:G13) -> 80
A11: Quarta (Almoço) #2 | B11: 1 | C11: 1 | D11: 1 | E11: 5 | F11: 14 | G11: =SUM(B11:F11) -> 22
A12: Quarta (Janta) | B12: 0 | C12: 1 | D12: 9 | E12: 11 | F12: 1 | G12: =SUM(B12:F12) -> 22
A13: Quarta (Janta) #2 | B13: 1 | C13: 0 | D13: 4 | E13: 2 | F13: 8 | G13: =SUM(B13:F13) -> 15
A14: Quinta (Almoço) | G14: =SUM(B14:F14) -> 0 | H14: =SUM(G14:G17) -> 0
A15: Quinta (Almoço) #2 | G15: =SUM(B15:F15) -> 0
A16: Quinta (Janta) | G16: =SUM(B16:F16) -> 0
A17: Quinta (Janta) #2 | G17: =SUM(B17:F17) -> 0
A18: Sexta (Almoço) | B18: 3 | C18: 0 | D18: 4 | E18: 7 | F18: 13 | G18: =SUM(B18:F18) -> 27 | H18: =SUM(G18:G21) -> 81
A19: Sexta (Almoço) #2 | B19: 2 | C19: 0 | D19: 0 | E19: 3 | F19: 15 | G19: =SUM(B19:F19) -> 20
A20: Sexta (Janta) | B20: 0 | C20: 0 | D20: 2 | E20: 0 | F20: 8 | G20: =SUM(B20:F20) -> 10
A21: Sexta (Janta) #2 | B21: 0 | C21: 0 | D21: 1 | E21: 0 | F21: 23 | G21: =SUM(B21:F21) -> 24
A22: Sábado | B22: 3 | C22: 0 | D22: 9 | E22: 3 | F22: 3 | G22: =SUM(B22:F22) -> 18 | H22: =SUM(G22:G24) -> 25
A23: Sábado #2 | B23: 3 | C23: 1 | D23: 3 | E23: 0 | F23: 0 | G23: =SUM(B23:F23) -> 7
A25: TOTAL DE ESTRELAS | B25: =SUM(B2:B23) -> 19 | C25: =SUM(C2:C23) -> 11 | D25: =SUM(D2:D23) -> 60 | E25: =SUM(E2:E23) -> 109 | F25: =SUM(F2:F23) -> 183 | G25: TOTAL DE VOTOS | H25: =SUM(G2:G23) -> 382
A26: MEDIA POR ESTRELA | B26: =AVERAGE(B2:B23) -> 1.0555556 | C26: =AVERAGE(C2:C23) -> 0.61111111 | D26: =AVERAGE(D2:D23) -> 3.3333333 | E26: =AVERAGE(E2:E23) -> 6.0555556 | F26: =AVERAGE(F2:F23) -> 10.166667 | G26: MÉDIA DAS ESTRELAS | H26: =SUM(B25*1,C25*2,D25*3,E25*4,F25*5)/H25 -> 4.1151832
G27: MÉDIA ANTERIOR | H27: ='SEMANA 32'!H26 -> 3.8159722 | I27: =_xlfn.CONCAT("", (H26-H27)/H27, "%") -> 0,0784101682157507%

Sheet SEMANA 34
B1: 🌟 | C1: 🌟🌟 | D1: 🌟🌟🌟 | E1: 🌟🌟🌟🌟 | F1: 🌟🌟🌟🌟🌟 | G1: TOTAL DE VOTOS / REFEIÇÃO | H1: TOTAL POR DIA
A2: Segunda (Almoço) | B2: 2 | C2: 2 | D2: 18 | E2: 8 | F2: 3 | G2: =SUM(B2:F2) -> 33 | H2: =SUM(G2:G5) -> 166
A3: Segunda (Almoço) #2 | B3: 1 | C3: 4 | D3: 25 | E3: 11 | F3: 13 | G3: =SUM(B3:F3) -> 54
A4: Segunda (Janta) | B4: 0 | C4: 0 | D4: 1 | E4: 3 | F4: 29 | G4: =SUM(B4:F4) -> 33
A5: Segunda (Janta) #2 | B5: 2 | C5: 0 | D5: 4 | E5: 15 | F5: 25 | G5: =SUM(B5:F5) -> 46
A6: Terça (Almoço) | B6: 2 | C6: 0 | D6: 1 | E6: 6 | F6: 24 | G6: =SUM(B6:F6) -> 33 | H6: =SUM(G6:G9) -> 113
A7: Terça (Almoço) #2 | B7: 7 | C7: 5 | D7: 9 | E7: 11 | F7: 19 | G7: =SUM(B7:F7) -> 51
A8: Terça (Janta) | B8: 2 | C8: 0 | D8: 5 | E8: 3 | F8: 11 | G8: =SUM(B8:F8) -> 21
A9: Terça (Janta) #2 | B9: 0 | C9: 3 | D9: 2 | E9: 0 | F9: 3 | G9: =SUM(B9:F9) -> 8
A10: Quarta (Almoço) | B10: 1 | C10: 0 | D10: 5 | E10: 11 | F10: 8 | G10: =SUM(B10:F10) -> 25 | H10: =SUM(G10:G13) -> 156
A11: Quarta (Almoço) #2 | B11: 1 | C11: 2 | D11: 0 | E11: 23 | F11: 43 | G11: =SUM(B11:F11) -> 69
A12: Quarta (Janta) | B12: 1 | C12: 3 | D12: 4 | E12: 7 | F12: 10 | G12: =SUM(B12:F12) -> 25
A13: Quarta (Janta) #2 | B13: 1 | C13: 2 | D13: 1 | E13: 15 | F13: 18 | G13: =SUM(B13:F13) -> 37
A14: Quinta (Almoço) | B14: 0 | C14: 3 | D14: 6 | E14: 12 | F14: 7 | G14: =SUM(B14:F14) -> 28 | H14: =SUM(G14:G17) -> 134
A15: Quinta (Almoço) #2 | B15: 0 | C15: 5 | D15: 9 | E15: 22 | F15: 21 | G15: =SUM(B15:F15) -> 57
A16: Quinta (Janta) | B16: 2 | C16: 0 | D16: 1 | E16: 4 | F16: 18 | G16: =SUM(B16:F16) -> 25
A17: Quinta (Janta) #2 | B17: 0 | C17: 1 | D17: 1 | E17: 6 | F17: 16 | G17: =SUM(B17:F17) -> 24
A18: Sexta (Almoço) | B18: 0 | C18: 5 | D18: 10 | E18: 6 | F18: 3 | G18: =SUM(B18:F18) -> 24 | H18: =SUM(G18:G21) -> 131
A19: Sexta (Almoço) #2 | B19: 4 | C19: 0 | D19: 8 | E19: 9 | F19: 16 | G19: =SUM(B19:F19) -> 37
A20: Sexta (Janta) | B20: 0 | C20: 1 | D20: 0 | E20: 12 | F20: 23 | G20: =SUM(B20:F20) -> 36
A21: Sexta (Janta) #2 | B21: 0 | C21: 3 | D21: 7 | E21: 7 | F21: 17 | G21: =SUM(B21:F21) -> 34
A22: Sábado | B22: 0 | C22: 1 | D22: 0 | E22: 0 | F22: 6 | G22: =SUM(B22:F22) -> 7 | H22: =SUM(G22:G24) -> 19
A23: Sábado #2 | B23: 0 | C23: 0 | D23: 0 | E23: 0 | F23: 12 | G23: =SUM(B23:F23) -> 12
A25: TOTAL DE ESTRELAS | B25: =SUM(B2:B23) -> 26 | C25: =SUM(C2:C23) -> 40 | D25: =SUM(D2:D23) -> 117 | E25: =SUM(E2:E23) -> 191 | F25: =SUM(F2:F23) -> 345 | G25: TOTAL DE VOTOS | H25: =SUM(G2:G23) -> 719
A26: MEDIA POR ESTRELA | B26: =AVERAGE(B2:B23) -> 1.1818182 | C26: =AVERAGE(C2:C23) -> 1.8181818 | D26: =AVERAGE(D2:D23) -> 5.3181818 | E26: =AVERAGE(E2:E23) -> 8.6818182 | F26: =AVERAGE(F2:F23) -> 15.681818 | G26: MÉDIA DAS ESTRELAS | H26: =SUM(B25*1,C25*2,D25*3,E25*4,F25*5)/H25 -> 4.0973574
G27: MÉDIA ANTERIOR | H27: ='SEMANA 33'!H26 -> 4.1151832 | I27: =_xlfn.CONCAT("", (H26-H27)/H27, "%") -> -0,00433171601779411%

Sheet SEMANA 35
B1: 🌟 | C1: 🌟🌟 | D1: 🌟🌟🌟 | E1: 🌟🌟🌟🌟 | F1: 🌟🌟🌟🌟🌟 | G1: TOTAL DE VOTOS / REFEIÇÃO | H1: TOTAL POR DIA
A2: Segunda (Almoço) | B2: 3 | C2: 4 | D2: 4 | E2: 15 | F2: 7 | G2: =SUM(B2:F2) -> 33 | H2: =SUM(G2:G5) -> 145
A3: Segunda (Almoço) #2 | B3: 10 | C3: 7 | D3: 8 | E3: 10 | F3: 18 | G3: =SUM(B3:F3) -> 53
A4: Segunda (Janta) | B4: 0 | C4: 2 | D4: 1 | E4: 7 | F4: 13 | G4: =SUM(B4:F4) -> 23
A5: Segunda (Janta) #2 | B5: 1 | C5: 0 | D5: 2 | E5: 7 | F5: 26 | G5: =SUM(B5:F5) -> 36
A6: Terça (Almoço) | B6: 0 | C6: 1 | D6: 4 | E6: 21 | F6: 7 | G6: =SUM(B6:F6) -> 33 | H6: =SUM(G6:G9) -> 146
A7: Terça (Almoço) #2 | B7: 5 | C7: 1 | D7: 9 | E7: 22 | F7: 12 | G7: =SUM(B7:F7) -> 49
A8: Terça (Janta) | B8: 0 | C8: 0 | D8: 8 | E8: 5 | F8: 12 | G8: =SUM(B8:F8) -> 25
A9: Terça (Janta) #2 | B9: 3 | C9: 1 | D9: 15 | E9: 13 | F9: 7 | G9: =SUM(B9:F9) -> 39
A10: Quarta (Almoço) | B10: 0 | C10: 0 | D10: 3 | E10: 13 | F10: 3 | G10: =SUM(B10:F10) -> 19 | H10: =SUM(G10:G13) -> 161
A11: Quarta (Almoço) #2 | B11: 8 | C11: 2 | D11: 10 | E11: 28 | F11: 14 | G11: =SUM(B11:F11) -> 62
A12: Quarta (Janta) | B12: 0 | C12: 0 | D12: 10 | E12: 16 | F12: 2 | G12: =SUM(B12:F12) -> 28
A13: Quarta (Janta) #2 | B13: 0 | C13: 5 | D13: 11 | E13: 17 | F13: 19 | G13: =SUM(B13:F13) -> 52
A14: Quinta (Almoço) | B14: 1 | C14: 0 | D14: 4 | E14: 11 | F14: 5 | G14: =SUM(B14:F14) -> 21 | H14: =SUM(G14:G17) -> 139
A15: Quinta (Almoço) #2 | B15: 0 | C15: 2 | D15: 12 | E15: 7 | F15: 18 | G15: =SUM(B15:F15) -> 39
A16: Quinta (Janta) | B16: 1 | C16: 0 | D16: 4 | E16: 20 | F16: 18 | G16: =SUM(B16:F16) -> 43
A17: Quinta (Janta) #2 | B17: 0 | C17: 0 | D17: 3 | E17: 8 | F17: 25 | G17: =SUM(B17:F17) -> 36
A18: Sexta (Almoço) | B18: 3 | C18: 1 | D18: 1 | E18: 13 | F18: 32 | G18: =SUM(B18:F18) -> 50 | H18: =SUM(G18:G21) -> 156
A19: Sexta (Almoço) #2 | B19: 1 | C19: 0 | D19: 11 | E19: 7 | F19: 37 | G19: =SUM(B19:F19) -> 56
A20: Sexta (Janta) | B20: 1 | C20: 0 | D20: 5 | E20: 4 | F20: 12 | G20: =SUM(B20:F20) -> 22
A21: Sexta (Janta) #2 | B21: 0 | C21: 0 | D21: 8 | E21: 5 | F21: 15 | G21: =SUM(B21:F21) -> 28
A22: Sábado | G22: =SUM(B22:F22) -> 0 | H22: =SUM(G22:G24) -> 0
A23: Sábado #2 | G23: =SUM(B23:F23) -> 0
A25: TOTAL DE ESTRELAS | B25: =SUM(B2:B23) -> 37 | C25: =SUM(C2:C23) -> 26 | D25: =SUM(D2:D23) -> 133 | E25: =SUM(E2:E23) -> 249 | F25: =SUM(F2:F23) -> 302 | G25: TOTAL DE VOTOS | H25: =SUM(G2:G23) -> 747
A26: MEDIA POR ESTRELA | B26: =AVERAGE(B2:B23) -> 1.85 | C26: =AVERAGE(C2:C23) -> 1.3 | D26: =AVERAGE(D2:D23) -> 6.65 | E26: =AVERAGE(E2:E23) -> 12.45 | F26: =AVERAGE(F2:F23) -> 15.1 | G26: MÉDIA DAS ESTRELAS | H26: =SUM(B25*1,C25*2,D25*3,E25*4,F25*5)/H25 -> 4.0080321
G27: MÉDIA ANTERIOR | H27: ='SEMANA 34'!H26 -> 4.0973574 | I27: =_xlfn.CONCAT("", (H26-H27)/H27, "%") -> -0,0218007126946345%

Sheet SEMANA 36
B1: 🌟 | C1: 🌟🌟 | D1: 🌟🌟🌟 | E1: 🌟🌟🌟🌟 | F1: 🌟🌟🌟🌟🌟 | G1: TOTAL DE VOTOS / REFEIÇÃO | H1: TOTAL POR DIA
A2: Segunda (Almoço) | B2: 2 | C2: 3 | D2: 6 | E2: 15 | F2: 10 | G2: =SUM(B2:F2) -> 36 | H2: =SUM(G2:G5) -> 181
A3: Segunda (Almoço) #2 | B3: 3 | C3: 6 | D3: 19 | E3: 26 | F3: 13 | G3: =SUM(B3:F3) -> 67
A4: Segunda (Janta) | B4: 0 | C4: 0 | D4: 5 | E4: 4 | F4: 19 | G4: =SUM(B4:F4) -> 28
A5: Segunda (Janta) #2 | B5: 4 | C5: 2 | D5: 5 | E5: 14 | F5: 25 | G5: =SUM(B5:F5) -> 50
A6: Terça (Almoço) | B6: 1 | C6: 1 | D6: 5 | E6: 18 | F6: 15 | G6: =SUM(B6:F6) -> 40 | H6: =SUM(G6:G9) -> 185
A7: Terça (Almoço) #2 | B7: 2 | C7: 2 | D7: 4 | E7: 20 | F7: 34 | G7: =SUM(B7:F7) -> 62
A8: Terça (Janta) | B8: 0 | C8: 0 | D8: 4 | E8: 15 | F8: 17 | G8: =SUM(B8:F8) -> 36
A9: Terça (Janta) #2 | B9: 1 | C9: 2 | D9: 1 | E9: 19 | F9: 24 | G9: =SUM(B9:F9) -> 47
A10: Quarta (Almoço) | B10: 0 | C10: 0 | D10: 6 | E10: 14 | F10: 14 | G10: =SUM(B10:F10) -> 34 | H10: =SUM(G10:G13) -> 156
A11: Quarta (Almoço) #2 | B11: 2 | C11: 0 | D11: 16 | E11: 14 | F11: 17 | G11: =SUM(B11:F11) -> 49
A12: Quarta (Janta) | B12: 4 | C12: 1 | D12: 2 | E12: 3 | F12: 24 | G12: =SUM(B12:F12) -> 34
A13: Quarta (Janta) #2 | B13: 2 | C13: 0 | D13: 0 | E13: 2 | F13: 35 | G13: =SUM(B13:F13) -> 39
A14: Quinta (Almoço) | B14: 2 | C14: 1 | D14: 1 | E14: 4 | F14: 16 | G14: =SUM(B14:F14) -> 24 | H14: =SUM(G14:G17) -> 130
A15: Quinta (Almoço) #2 | B15: 1 | C15: 6 | D15: 10 | E15: 19 | F15: 15 | G15: =SUM(B15:F15) -> 51
A16: Quinta (Janta) | B16: 0 | C16: 0 | D16: 0 | E16: 6 | F16: 8 | G16: =SUM(B16:F16) -> 14
A17: Quinta (Janta) #2 | B17: 0 | C17: 2 | D17: 3 | E17: 24 | F17: 12 | G17: =SUM(B17:F17) -> 41
A18: Sexta (Almoço) | B18: 1 | C18: 0 | D18: 3 | E18: 7 | F18: 10 | G18: =SUM(B18:F18) -> 21 | H18: =SUM(G18:G21) -> 85
A19: Sexta (Almoço) #2 | B19: 2 | C19: 3 | D19: 4 | E19: 12 | F19: 17 | G19: =SUM(B19:F19) -> 38
A20: Sexta (Janta) | B20: 2 | C20: 1 | D20: 0 | E20: 4 | F20: 5 | G20: =SUM(B20:F20) -> 12
A21: Sexta (Janta) #2 | B21: 0 | C21: 0 | D21: 0 | E21: 7 | F21: 7 | G21: =SUM(B21:F21) -> 14
A22: Sábado | G22: =SUM(B22:F22) -> 0 | H22: =SUM(G22:G24) -> 0
A23: Sábado #2 | G23: =SUM(B23:F23) -> 0
A25: TOTAL DE ESTRELAS | B25: =SUM(B2:B23) -> 29 | C25: =SUM(C2:C23) -> 30 | D25: =SUM(D2:D23) -> 94 | E25: =SUM(E2:E23) -> 247 | F25: =SUM(F2:F23) -> 337 | G25: TOTAL DE VOTOS | H25: =SUM(G2:G23) -> 737
A26: MEDIA POR ESTRELA | B26: =AVERAGE(B2:B23) -> 1.45 | C26: =AVERAGE(C2:C23) -> 1.5 | D26: =AVERAGE(D2:D23) -> 4.7 | E26: =AVERAGE(E2:E23) -> 12.35 | F26: =AVERAGE(F2:F23) -> 16.85 | G26: MÉDIA DAS ESTRELAS | H26: =SUM(B25*1,C25*2,D25*3,E25*4,F25*5)/H25 -> 4.1302578
G27: MÉDIA ANTERIOR | H27: ='SEMANA 35'!H26 -> 4.0080321 | I27: =_xlfn.CONCAT("", (H26-H27)/H27, "%") -> 0,0304951830390768%

Sheet SEMANA 37
B1: 🌟 | C1: 🌟🌟 | D1: 🌟🌟🌟 | E1: 🌟🌟🌟🌟 | F1: 🌟🌟🌟🌟🌟 | G1: TOTAL DE VOTOS / REFEIÇÃO | H1: TOTAL POR DIA
A2: Segunda (Almoço) | B2: 0 | C2: 2 | D2: 2 | E2: 12 | F2: 7 | G2: =SUM(B2:F2) -> 23 | H2: =SUM(G2:G5) -> 165
A3: Segunda (Almoço) #2 | B3: 0 | C3: 0 | D3: 14 | E3: 25 | F3: 10 | G3: =SUM(B3:F3) -> 49
A4: Segunda (Janta) | B4: 2 | C4: 0 | D4: 4 | E4: 8 | F4: 22 | G4: =SUM(B4:F4) -> 36
A5: Segunda (Janta) #2 | B5: 1 | C5: 0 | D5: 2 | E5: 7 | F5: 47 | G5: =SUM(B5:F5) -> 57
A6: Terça (Almoço) | B6: 8 | C6: 4 | D6: 3 | E6: 19 | F6: 1 | G6: =SUM(B6:F6) -> 35 | H6: =SUM(G6:G9) -> 132
A7: Terça (Almoço) #2 | B7: 2 | C7: 1 | D7: 8 | E7: 19 | F7: 7 | G7: =SUM(B7:F7) -> 37
A8: Terça (Janta) | B8: 0 | C8: 0 | D8: 2 | E8: 15 | F8: 5 | G8: =SUM(B8:F8) -> 22
A9: Terça (Janta) #2 | B9: 1 | C9: 2 | D9: 7 | E9: 11 | F9: 17 | G9: =SUM(B9:F9) -> 38
A10: Quarta (Almoço) | B10: 0 | C10: 1 | D10: 7 | E10: 12 | F10: 3 | G10: =SUM(B10:F10) -> 23 | H10: =SUM(G10:G13) -> 123
A11: Quarta (Almoço) #2 | B11: 2 | C11: 1 | D11: 3 | E11: 9 | F11: 22 | G11: =SUM(B11:F11) -> 37
A12: Quarta (Janta) | B12: 1 | C12: 0 | D12: 2 | E12: 8 | F12: 16 | G12: =SUM(B12:F12) -> 27
A13: Quarta (Janta) #2 | B13: 0 | C13: 1 | D13: 2 | E13: 8 | F13: 25 | G13: =SUM(B13:F13) -> 36
A14: Quinta (Almoço) | B14: 2 | C14: 1 | D14: 5 | E14: 9 | F14: 1 | G14: =SUM(B14:F14) -> 18 | H14: =SUM(G14:G17) -> 111
A15: Quinta (Almoço) #2 | B15: 2 | C15: 2 | D15: 6 | E15: 21 | F15: 3 | G15: =SUM(B15:F15) -> 34
A16: Quinta (Janta) | B16: 4 | C16: 6 | D16: 4 | E16: 2 | F16: 8 | G16: =SUM(B16:F16) -> 24
A17: Quinta (Janta) #2 | B17: 7 | C17: 3 | D17: 8 | E17: 10 | F17: 7 | G17: =SUM(B17:F17) -> 35
A18: Sexta (Almoço) | B18: 0 | C18: 1 | D18: 1 | E18: 3 | F18: 30 | G18: =SUM(B18:F18) -> 35 | H18: =SUM(G18:G21) -> 121
A19: Sexta (Almoço) #2 | B19: 1 | C19: 0 | D19: 4 | E19: 13 | F19: 29 | G19: =SUM(B19:F19) -> 47
A20: Sexta (Janta) | B20: 0 | C20: 0 | D20: 2 | E20: 4 | F20: 5 | G20: =SUM(B20:F20) -> 11
A21: Sexta (Janta) #2 | B21: 0 | C21: 2 | D21: 4 | E21: 6 | F21: 16 | G21: =SUM(B21:F21) -> 28
A22: Sábado | B22: 1 | C22: 0 | D22: 1 | E22: 3 | F22: 9 | G22: =SUM(B22:F22) -> 14 | H22: =SUM(G22:G24) -> 53
A23: Sábado #2 | B23: 0 | C23: 0 | D23: 2 | E23: 9 | F23: 28 | G23: =SUM(B23:F23) -> 39
A25: TOTAL DE ESTRELAS | B25: =SUM(B2:B23) -> 34 | C25: =SUM(C2:C23) -> 27 | D25: =SUM(D2:D23) -> 93 | E25: =SUM(E2:E23) -> 233 | F25: =SUM(F2:F23) -> 318 | G25: TOTAL DE VOTOS | H25: =SUM(G2:G23) -> 705
A26: MEDIA POR ESTRELA | B26: =AVERAGE(B2:B23) -> 1.5454545 | C26: =AVERAGE(C2:C23) -> 1.2272727 | D26: =AVERAGE(D2:D23) -> 4.2272727 | E26: =AVERAGE(E2:E23) -> 10.590909 | F26: =AVERAGE(F2:F23) -> 14.454545 | G26: MÉDIA DAS ESTRELAS | H26: =SUM(B25*1,C25*2,D25*3,E25*4,F25*5)/H25 -> 4.0978723
G27: MÉDIA ANTERIOR | H27: ='SEMANA 36'!H26 -> 4.1302578 | I27: =_xlfn.CONCAT("", (H26-H27)/H27, "%") -> -0,00784102664467253%

Sheet SEMANA 38
B1: 🌟 | C1: 🌟🌟 | D1: 🌟🌟🌟 | E1: 🌟🌟🌟🌟 | F1: 🌟🌟🌟🌟🌟 | G1: TOTAL DE VOTOS / REFEIÇÃO | H1: TOTAL POR DIA
A2: Segunda (Almoço) | B2: 0 | C2: 1 | D2: 1 | E2: 6 | F2: 16 | G2: =SUM(B2:F2) -> 24 | H2: =SUM(G2:G5) -> 136
A3: Segunda (Almoço) #2 | B3: 1 | C3: 0 | D3: 3 | E3: 9 | F3: 26 | G3: =SUM(B3:F3) -> 39
A4: Segunda (Janta) | B4: 1 | C4: 0 | D4: 1 | E4: 7 | F4: 19 | G4: =SUM(B4:F4) -> 28
A5: Segunda (Janta) #2 | B5: 4 | C5: 1 | D5: 6 | E5: 14 | F5: 20 | G5: =SUM(B5:F5) -> 45
A6: Terça (Almoço) | B6: 1 | C6: 5 | D6: 2 | E6: 5 | F6: 4 | G6: =SUM(B6:F6) -> 17 | H6: =SUM(G6:G9) -> 130
A7: Terça (Almoço) #2 | B7: 4 | C7: 7 | D7: 19 | E7: 20 | F7: 5 | G7: =SUM(B7:F7) -> 55
A8: Terça (Janta) | B8: 1 | C8: 2 | D8: 7 | E8: 8 | F8: 9 | G8: =SUM(B8:F8) -> 27
A9: Terça (Janta) #2 | B9: 2 | C9: 0 | D9: 5 | E9: 7 | F9: 17 | G9: =SUM(B9:F9) -> 31
A10: Quarta (Almoço) | B10: 3 | C10: 3 | D10: 2 | E10: 4 | F10: 10 | G10: =SUM(B10:F10) -> 22 | H10: =SUM(G10:G13) -> 131
A11: Quarta (Almoço) #2 | B11: 0 | C11: 0 | D11: 4 | E11: 23 | F11: 10 | G11: =SUM(B11:F11) -> 37
A12: Quarta (Janta) | B12: 1 | C12: 1 | D12: 2 | E12: 11 | F12: 12 | G12: =SUM(B12:F12) -> 27
A13: Quarta (Janta) #2 | B13: 1 | C13: 0 | D13: 9 | E13: 17 | F13: 18 | G13: =SUM(B13:F13) -> 45
A14: Quinta (Almoço) | B14: 1 | C14: 1 | D14: 14 | E14: 8 | F14: 1 | G14: =SUM(B14:F14) -> 25 | H14: =SUM(G14:G17) -> 130
A15: Quinta (Almoço) #2 | B15: 5 | C15: 8 | D15: 20 | E15: 11 | F15: 6 | G15: =SUM(B15:F15) -> 50
A16: Quinta (Janta) | B16: 2 | C16: 6 | D16: 4 | E16: 5 | F16: 9 | G16: =SUM(B16:F16) -> 26
A17: Quinta (Janta) #2 | B17: 0 | C17: 3 | D17: 5 | E17: 13 | F17: 8 | G17: =SUM(B17:F17) -> 29
A18: Sexta (Almoço) | B18: 0 | C18: 2 | D18: 6 | E18: 8 | F18: 3 | G18: =SUM(B18:F18) -> 19 | H18: =SUM(G18:G21) -> 97
A19: Sexta (Almoço) #2 | B19: 1 | C19: 6 | D19: 6 | E19: 17 | F19: 8 | G19: =SUM(B19:F19) -> 38
A20: Sexta (Janta) | B20: 0 | C20: 3 | D20: 0 | E20: 1 | F20: 17 | G20: =SUM(B20:F20) -> 21
A21: Sexta (Janta) #2 | B21: 0 | C21: 0 | D21: 0 | E21: 4 | F21: 15 | G21: =SUM(B21:F21) -> 19
A22: Sábado | B22: 1 | C22: 5 | D22: 3 | E22: 4 | F22: 7 | G22: =SUM(B22:F22) -> 20 | H22: =SUM(G22:G24) -> 35
A23: Sábado #2 | B23: 1 | C23: 1 | D23: 2 | E23: 1 | F23: 10 | G23: =SUM(B23:F23) -> 15
A25: TOTAL DE ESTRELAS | B25: =SUM(B2:B23) -> 30 | C25: =SUM(C2:C23) -> 55 | D25: =SUM(D2:D23) -> 121 | E25: =SUM(E2:E23) -> 203 | F25: =SUM(F2:F23) -> 250 | G25: TOTAL DE VOTOS | H25: =SUM(G2:G23) -> 659
A26: MEDIA POR ESTRELA | B26: =AVERAGE(B2:B23) -> 1.3636364 | C26: =AVERAGE(C2:C23) -> 2.5 | D26: =AVERAGE(D2:D23) -> 5.5 | E26: =AVERAGE(E2:E23) -> 9.2272727 | F26: =AVERAGE(F2:F23) -> 11.363636 | G26: MÉDIA DAS ESTRELAS | H26: =SUM(B25*1,C25*2,D25*3,E25*4,F25*5)/H25 -> 3.892261
G27: MÉDIA ANTERIOR | H27: ='SEMANA 37'!H26 -> 4.0978723 | I27: =_xlfn.CONCAT("", (H26-H27)/H27, "%") -> -0,0501751450087218%

Sheet SEMANA 39
B1: 🌟 | C1: 🌟🌟 | D1: 🌟🌟🌟 | E1: 🌟🌟🌟🌟 | F1: 🌟🌟🌟🌟🌟 | G1: TOTAL DE VOTOS / REFEIÇÃO | H1: TOTAL POR DIA
A2: Segunda (Almoço) | B2: 1 | C2: 1 | D2: 8 | E2: 4 | F2: 4 | G2: =SUM(B2:F2) -> 18 | H2: =SUM(G2:G5) -> 109
A3: Segunda (Almoço) #2 | B3: 0 | C3: 1 | D3: 12 | E3: 12 | F3: 4 | G3: =SUM(B3:F3) -> 29
A4: Segunda (Janta) | B4: 0 | C4: 4 | D4: 8 | E4: 7 | F4: 6 | G4: =SUM(B4:F4) -> 25
A5: Segunda (Janta) #2 | B5: 3 | C5: 9 | D5: 15 | E5: 8 | F5: 2 | G5: =SUM(B5:F5) -> 37
A6: Terça (Almoço) | B6: 2 | C6: 0 | D6: 2 | E6: 4 | F6: 11 | G6: =SUM(B6:F6) -> 19 | H6: =SUM(G6:G9) -> 116
A7: Terça (Almoço) #2 | B7: 0 | C7: 0 | D7: 8 | E7: 21 | F7: 9 | G7: =SUM(B7:F7) -> 38
